Workbook

Sheet 0_Inicio
B2: LABORATORIO CCI - Concurso Carteras de Inversion
B3: Herramientas para estudiar y practicar teoria de portafolios y gestionar tu cartera durante el concurso.
B5: COLORES
B6: Celda amarilla | C6: Dato que TU ingresas o puedes cambiar.
B7: Celda verde | C7: Resultado clave calculado con formulas (no escribir encima).
B8: Texto rojo | C8: Alertas automaticas (caja negativa, concentracion excesiva, etc.).
B10: HOJA | C10: PARA QUE SIRVE
B11: 1_Precios | C11: Precios diarios de 5 acciones y el IPSA. DATOS FICTICIOS para practicar: reemplazalos por datos reales (ver abajo).
B12: 2_Retornos | C12: Retornos diarios, retorno y volatilidad anualizados, Sharpe, retorno acumulado.
B13: 3_Cov_Correl | C13: Matriz de covarianzas y correlaciones (con mapa de calor). Base de la diversificacion.
B14: 4_Frontera_2A | C14: Frontera eficiente con 2 activos: cambia la correlacion y mira como cambia el riesgo. Portafolio de minima varianza.
B15: 5_Cartera | C15: Tu cartera de N acciones: pesos editables, retorno, riesgo, Sharpe, beta, Treynor, alfa de Jensen, tracking error, drawdown. Optimizable con Solver.
B16: 6_Beta_CAPM | C16: Beta de cada accion vs IPSA (regresion), R2 y retorno exigido por CAPM.
B17: 7_Tecnico | C17: Analisis tecnico de la accion que elijas: medias moviles 20/50, cruces, RSI(14) y bandas de Bollinger.
B18: 8_Drawdown | C18: Caida maxima desde el peak de cada activo.
... B23: 13_Plan_Estudio | C23: Plan de 21 dias para dominar el tema, con avance automatico.
B26: COMO PONER DATOS REALES
C27: 1) Yahoo Finance: busca el ticker con sufijo .SN (ej. SQM-B.SN, CHILE.SN, FALABELLA.SN). Indice: ^IPSA. Pestana "Historical Data" > Descargar.
C28: 2) Alternativas: Investing.com (Chile), TradingView, terminal de tu corredora o el sitio de la Bolsa de Santiago / nuam.
C29: 3) Pega los precios de CIERRE (ajustados por dividendos si vas a medir retorno total) en 1_Precios, misma estructura (columna = accion, fila = fecha).
C30: 4) Cambia los nombres de la fila 1 de 1_Precios por los tickers reales: todas las hojas se actualizan solas.
C31: 5) Si cambias el numero de filas, ajusta los rangos (las formulas usan filas 2 a 253 = 252 dias habiles ~ 1 ano).
C32: ADVERTENCIA: los datos de ejemplo son simulados con un modelo de mercado. No representan precios reales de ninguna empresa.

Sheet 1_Precios
A1: Fecha | B1: BANCO | C1: RETAIL | D1: MINERA | E1: ENERGIA | F1: CONSUMO | G1: IPSA | I1: DATOS FICTICIOS (simulados). Reemplazar por precios reales de cierre.
A2: 45659 | B2: 5200 | C2: 2100 | D2: 41000 | E2: 95 | F2: 6800 | G2: 7000
A3: 45660 | B3: 5199.25 | C3: 2137 | D3: 41549.37 | E3: 95.88 | F3: 6847.64 | G3: 7060.38
A4: 45663 | B4: 5218.97 | C4: 2120 | D4: 42744.95 | E4: 96.07 | F4: 6904.96 | G4: 7117.14
A5: 45664 | B5: 5055.01 | C5: 2043.88 | D5: 40630.26 | E5: 95.61 | F5: 6780.96 | G5: 6986.28
A6: 45665 | B6: 5060.47 | C6: 2073.95 | D6: 42226.06 | E6: 95.36 | F6: 6722.13 | G6: 6979.31
A7: 45666 | B7: 5007.77 | C7: 2059.43 | D7: 40841.1 | E7: 94.28 | F7: 6854.64 | G7: 7019.77
A8: 45667 | B8: 4985.59 | C8: 2110.26 | D8: 40941.19 | E8: 94.6 | F8: 6857.1 | G8: 7051.07
A9: 45670 | B9: 4901.59 | C9: 2138.76 | D9: 40006.07 | E9: 95 | F9: 6889.08 | G9: 6985.11
A10: 45671 | B10: 4826.61 | C10: 2182.11 | D10: 38906.16 | E10: 94.44 | F10: 6750.42 | G10: 6937.72
A11: 45672 | B11: 4815.24 | C11: 2224.17 | D11: 39772.57 | E11: 94.9 | F11: 6787.39 | G11: 6957.78
A12: 45673 | B12: 4719.9 | C12: 2229.04 | D12: 39014.02 | E12: 94.11 | F12: 6672.32 | G12: 6879.11
A13: 45674 | B13: 4693.18 | C13: 2205.28 | D13: 39309.44 | E13: 93.56 | F13: 6685.45 | G13: 6868.23
... A253: 46010 | B253: 4453.76 | C253: 3260.19 | D253: 37142.42 | E253: 96.07 | F253: 6860.26 | G253: 6558.76

Sheet 2_Retornos
A1: Fecha | B1: BANCO | C1: RETAIL | D1: MINERA | E1: ENERGIA | F1: CONSUMO | G1: IPSA | I1: PARAMETROS
A2: ='1_Precios'!A2 -> 0 | B2: ='1_Precios'!B2/'1_Precios'!B1-1 -> 0 | C2: ='1_Precios'!C2/'1_Precios'!C1-1 -> 0 | D2: ='1_Precios'!D2/'1_Precios'!D1-1 -> 0 | E2: ='1_Precios'!E2/'1_Precios'!E1-1 -> 0 | F2: ='1_Precios'!F2/'1_Precios'!F1-1 -> 0 | G2: ='1_Precios'!G2/'1_Precios'!G1-1 -> 0 | I2: Tasa libre de riesgo anual (rf) | J2: 0.0475 | K2: Ej.: TPM o BCP/BTP en pesos. Editable.
A3: ='1_Precios'!A3 -> 0 | B3: ='1_Precios'!B3/'1_Precios'!B2-1 -> 0 | C3: ='1_Precios'!C3/'1_Precios'!C2-1 -> 0 | D3: ='1_Precios'!D3/'1_Precios'!D2-1 -> 0 | E3: ='1_Precios'!E3/'1_Precios'!E2-1 -> 0 | F3: ='1_Precios'!F3/'1_Precios'!F2-1 -> 0 | G3: ='1_Precios'!G3/'1_Precios'!G2-1 -> 0 | I3: Dias habiles por ano | J3: 252
A4: ='1_Precios'!A4 -> 0 | B4: ='1_Precios'!B4/'1_Precios'!B3-1 -> 0 | C4: ='1_Precios'!C4/'1_Precios'!C3-1 -> 0 | D4: ='1_Precios'!D4/'1_Precios'!D3-1 -> 0 | E4: ='1_Precios'!E4/'1_Precios'!E3-1 -> 0 | F4: ='1_Precios'!F4/'1_Precios'!F3-1 -> 0 | G4: ='1_Precios'!G4/'1_Precios'!G3-1 -> 0
A5: ='1_Precios'!A5 -> 0 | B5: ='1_Precios'!B5/'1_Precios'!B4-1 -> 0 | C5: ='1_Precios'!C5/'1_Precios'!C4-1 -> 0 | D5: ='1_Precios'!D5/'1_Precios'!D4-1 -> 0 | E5: ='1_Precios'!E5/'1_Precios'!E4-1 -> 0 | F5: ='1_Precios'!F5/'1_Precios'!F4-1 -> 0 | G5: ='1_Precios'!G5/'1_Precios'!G4-1 -> 0 | I5: ESTADISTICO | J5: BANCO | K5: RETAIL | L5: MINERA | M5: ENERGIA | N5: CONSUMO | O5: IPSA
A6: ='1_Precios'!A6 -> 0 | B6: ='1_Precios'!B6/'1_Precios'!B5-1 -> 0 | C6: ='1_Precios'!C6/'1_Precios'!C5-1 -> 0 | D6: ='1_Precios'!D6/'1_Precios'!D5-1 -> 0 | E6: ='1_Precios'!E6/'1_Precios'!E5-1 -> 0 | F6: ='1_Precios'!F6/'1_Precios'!F5-1 -> 0 | G6: ='1_Precios'!G6/'1_Precios'!G5-1 -> 0 | I6: Retorno medio diario | J6: =AVERAGE(B2:B252) -> 0 | K6: =AVERAGE(C2:C252) -> 0 | L6: =AVERAGE(D2:D252) -> 0 | M6: =AVERAGE(E2:E252) -> 0 | N6: =AVERAGE(F2:F252) -> 0 | O6: =AVERAGE(G2:G252) -> 0
A7: ='1_Precios'!A7 -> 0 | B7: ='1_Precios'!B7/'1_Precios'!B6-1 -> 0 | C7: ='1_Precios'!C7/'1_Precios'!C6-1 -> 0 | D7: ='1_Precios'!D7/'1_Precios'!D6-1 -> 0 | E7: ='1_Precios'!E7/'1_Precios'!E6-1 -> 0 | F7: ='1_Precios'!F7/'1_Precios'!F6-1 -> 0 | G7: ='1_Precios'!G7/'1_Precios'!G6-1 -> 0 | I7: Retorno anualizado (compuesto) | J7: =(1+J6)^$J$3-1 -> 0 | K7: =(1+K6)^$J$3-1 -> 0 | L7: =(1+L6)^$J$3-1 -> 0 | M7: =(1+M6)^$J$3-1 -> 0 | N7: =(1+N6)^$J$3-1 -> 0 | O7: =(1+O6)^$J$3-1 -> 0
A8: ='1_Precios'!A8 -> 0 | B8: ='1_Precios'!B8/'1_Precios'!B7-1 -> 0 | C8: ='1_Precios'!C8/'1_Precios'!C7-1 -> 0 | D8: ='1_Precios'!D8/'1_Precios'!D7-1 -> 0 | E8: ='1_Precios'!E8/'1_Precios'!E7-1 -> 0 | F8: ='1_Precios'!F8/'1_Precios'!F7-1 -> 0 | G8: ='1_Precios'!G8/'1_Precios'!G7-1 -> 0 | I8: Volatilidad diaria | J8: =_xlfn.STDEV.S(B2:B252) -> 0 | K8: =_xlfn.STDEV.S(C2:C252) -> 0 | L8: =_xlfn.STDEV.S(D2:D252) -> 0 | M8: =_xlfn.STDEV.S(E2:E252) -> 0 | N8: =_xlfn.STDEV.S(F2:F252) -> 0 | O8: =_xlfn.STDEV.S(G2:G252) -> 0
A9: ='1_Precios'!A9 -> 0 | B9: ='1_Precios'!B9/'1_Precios'!B8-1 -> 0 | C9: ='1_Precios'!C9/'1_Precios'!C8-1 -> 0 | D9: ='1_Precios'!D9/'1_Precios'!D8-1 -> 0 | E9: ='1_Precios'!E9/'1_Precios'!E8-1 -> 0 | F9: ='1_Precios'!F9/'1_Precios'!F8-1 -> 0 | G9: ='1_Precios'!G9/'1_Precios'!G8-1 -> 0 | I9: Volatilidad anualizada | J9: =J8*SQRT($J$3) -> 0 | K9: =K8*SQRT($J$3) -> 0 | L9: =L8*SQRT($J$3) -> 0 | M9: =M8*SQRT($J$3) -> 0 | N9: =N8*SQRT($J$3) -> 0 | O9: =O8*SQRT($J$3) -> 0
A10: ='1_Precios'!A10 -> 0 | B10: ='1_Precios'!B10/'1_Precios'!B9-1 -> 0 | C10: ='1_Precios'!C10/'1_Precios'!C9-1 -> 0 | D10: ='1_Precios'!D10/'1_Precios'!D9-1 -> 0 | E10: ='1_Precios'!E10/'1_Precios'!E9-1 -> 0 | F10: ='1_Precios'!F10/'1_Precios'!F9-1 -> 0 | G10: ='1_Precios'!G10/'1_Precios'!G9-1 -> 0 | I10: Ratio de Sharpe anual | J10: =(J7-$J$2)/J9 -> 0 | K10: =(K7-$J$2)/K9 -> 0 | L10: =(L7-$J$2)/L9 -> 0 | M10: =(M7-$J$2)/M9 -> 0 | N10: =(N7-$J$2)/N9 -> 0 | O10: =(O7-$J$2)/O9 -> 0
A11: ='1_Precios'!A11 -> 0 | B11: ='1_Precios'!B11/'1_Precios'!B10-1 -> 0 | C11: ='1_Precios'!C11/'1_Precios'!C10-1 -> 0 | D11: ='1_Precios'!D11/'1_Precios'!D10-1 -> 0 | E11: ='1_Precios'!E11/'1_Precios'!E10-1 -> 0 | F11: ='1_Precios'!F11/'1_Precios'!F10-1 -> 0 | G11: ='1_Precios'!G11/'1_Precios'!G10-1 -> 0 | I11: Retorno acumulado periodo | J11: =INDEX('1_Precios'!B$2:B$253,252)/'1_Precios'!B$2-1 -> 0 | K11: =INDEX('1_Precios'!C$2:C$253,252)/'1_Precios'!C$2-1 -> 0 | L11: =INDEX('1_Precios'!D$2:D$253,252)/'1_Precios'!D$2-1 -> 0 | M11: =INDEX('1_Precios'!E$2:E$253,252)/'1_Precios'!E$2-1 -> 0 | N11: =INDEX('1_Precios'!F$2:F$253,252)/'1_Precios'!F$2-1 -> 0 | O11: =INDEX('1_Precios'!G$2:G$253,252)/'1_Precios'!G$2-1 -> 0
A12: ='1_Precios'!A12 -> 0 | B12: ='1_Precios'!B12/'1_Precios'!B11-1 -> 0 | C12: ='1_Precios'!C12/'1_Precios'!C11-1 -> 0 | D12: ='1_Precios'!D12/'1_Precios'!D11-1 -> 0 | E12: ='1_Precios'!E12/'1_Precios'!E11-1 -> 0 | F12: ='1_Precios'!F12/'1_Precios'!F11-1 -> 0 | G12: ='1_Precios'!G12/'1_Precios'!G11-1 -> 0 | I12: Mejor dia | J12: =MAX(B2:B252) -> 0 | K12: =MAX(C2:C252) -> 0 | L12: =MAX(D2:D252) -> 0 | M12: =MAX(E2:E252) -> 0 | N12: =MAX(F2:F252) -> 0 | O12: =MAX(G2:G252) -> 0
A13: ='1_Precios'!A13 -> 0 | B13: ='1_Precios'!B13/'1_Precios'!B12-1 -> 0 | C13: ='1_Precios'!C13/'1_Precios'!C12-1 -> 0 | D13: ='1_Precios'!D13/'1_Precios'!D12-1 -> 0 | E13: ='1_Precios'!E13/'1_Precios'!E12-1 -> 0 | F13: ='1_Precios'!F13/'1_Precios'!F12-1 -> 0 | G13: ='1_Precios'!G13/'1_Precios'!G12-1 -> 0 | I13: Peor dia | J13: =MIN(B2:B252) -> 0 | K13: =MIN(C2:C252) -> 0 | L13: =MIN(D2:D252) -> 0 | M13: =MIN(E2:E252) -> 0 | N13: =MIN(F2:F252) -> 0 | O13: =MIN(G2:G252) -> 0
A14: ='1_Precios'!A14 -> 0 | B14: ='1_Precios'!B14/'1_Precios'!B13-1 -> 0 | C14: ='1_Precios'!C14/'1_Precios'!C13-1 -> 0 | D14: ='1_Precios'!D14/'1_Precios'!D13-1 -> 0 | E14: ='1_Precios'!E14/'1_Precios'!E13-1 -> 0 | F14: ='1_Precios'!F14/'1_Precios'!F13-1 -> 0 | G14: ='1_Precios'!G14/'1_Precios'!G13-1 -> 0 | I14: % dias positivos | J14: =COUNTIF(B2:B252,">0")/COUNT(B2:B252) -> 0 | K14: =COUNTIF(C2:C252,">0")/COUNT(C2:C252) -> 0 | L14: =COUNTIF(D2:D252,">0")/COUNT(D2:D252) -> 0 | M14: =COUNTIF(E2:E252,">0")/COUNT(E2:E252) -> 0 | N14: =COUNTIF(F2:F252,">0")/COUNT(F2:F252) -> 0 | O14: =COUNTIF(G2:G252,">0")/COUNT(G2:G252) -> 0
A15: ='1_Precios'!A15 -> 0 | B15: ='1_Precios'!B15/'1_Precios'!B14-1 -> 0 | C15: ='1_Precios'!C15/'1_Precios'!C14-1 -> 0 | D15: ='1_Precios'!D15/'1_Precios'!D14-1 -> 0 | E15: ='1_Precios'!E15/'1_Precios'!E14-1 -> 0 | F15: ='1_Precios'!F15/'1_Precios'!F14-1 -> 0 | G15: ='1_Precios'!G15/'1_Precios'!G14-1 -> 0 | I15: Asimetria (skew) | J15: =SKEW(B2:B252) -> 0 | K15: =SKEW(C2:C252) -> 0 | L15: =SKEW(D2:D252) -> 0 | M15: =SKEW(E2:E252) -> 0 | N15: =SKEW(F2:F252) -> 0 | O15: =SKEW(G2:G252) -> 0
A16: ='1_Precios'!A16 -> 0 | B16: ='1_Precios'!B16/'1_Precios'!B15-1 -> 0 | C16: ='1_Precios'!C16/'1_Precios'!C15-1 -> 0 | D16: ='1_Precios'!D16/'1_Precios'!D15-1 -> 0 | E16: ='1_Precios'!E16/'1_Precios'!E15-1 -> 0 | F16: ='1_Precios'!F16/'1_Precios'!F15-1 -> 0 | G16: ='1_Precios'!G16/'1_Precios'!G15-1 -> 0 | I16: Curtosis (exceso) | J16: =KURT(B2:B252) -> 0 | K16: =KURT(C2:C252) -> 0 | L16: =KURT(D2:D252) -> 0 | M16: =KURT(E2:E252) -> 0 | N16: =KURT(F2:F252) -> 0 | O16: =KURT(G2:G252) -> 0
A17: ='1_Precios'!A17 -> 0 | B17: ='1_Precios'!B17/'1_Precios'!B16-1 -> 0 | C17: ='1_Precios'!C17/'1_Precios'!C16-1 -> 0 | D17: ='1_Precios'!D17/'1_Precios'!D16-1 -> 0 | E17: ='1_Precios'!E17/'1_Precios'!E16-1 -> 0 | F17: ='1_Precios'!F17/'1_Precios'!F16-1 -> 0 | G17: ='1_Precios'!G17/'1_Precios'!G16-1 -> 0
A18: ='1_Precios'!A18 -> 0 | B18: ='1_Precios'!B18/'1_Precios'!B17-1 -> 0 | C18: ='1_Precios'!C18/'1_Precios'!C17-1 -> 0 | D18: ='1_Precios'!D18/'1_Precios'!D17-1 -> 0 | E18: ='1_Precios'!E18/'1_Precios'!E17-1 -> 0 | F18: ='1_Precios'!F18/'1_Precios'!F17-1 -> 0 | G18: ='1_Precios'!G18/'1_Precios'!G17-1 -> 0 | I18: Como leer:
A19: ='1_Precios'!A19 -> 0 | B19: ='1_Precios'!B19/'1_Precios'!B18-1 -> 0 | C19: ='1_Precios'!C19/'1_Precios'!C18-1 -> 0 | D19: ='1_Precios'!D19/'1_Precios'!D18-1 -> 0 | E19: ='1_Precios'!E19/'1_Precios'!E18-1 -> 0 | F19: ='1_Precios'!F19/'1_Precios'!F18-1 -> 0 | G19: ='1_Precios'!G19/'1_Precios'!G18-1 -> 0 | I19: Volatilidad anual = vol diaria x RAIZ(252). Sharpe = (retorno anual - rf) / volatilidad anual: retorno por unidad de riesgo total. Curtosis > 0 = colas gordas (mas dias extremos que una normal).
A20: ='1_Precios'!A20 -> 0 | B20: ='1_Precios'!B20/'1_Precios'!B19-1 -> 0 | C20: ='1_Precios'!C20/'1_Precios'!C19-1 -> 0 | D20: ='1_Precios'!D20/'1_Precios'!D19-1 -> 0 | E20: ='1_Precios'!E20/'1_Precios'!E19-1 -> 0 | F20: ='1_Precios'!F20/'1_Precios'!F19-1 -> 0 | G20: ='1_Precios'!G20/'1_Precios'!G19-1 -> 0
A21: ='1_Precios'!A21 -> 0 | B21: ='1_Precios'!B21/'1_Precios'!B20-1 -> 0 | C21: ='1_Precios'!C21/'1_Precios'!C20-1 -> 0 | D21: ='1_Precios'!D21/'1_Precios'!D20-1 -> 0 | E21: ='1_Precios'!E21/'1_Precios'!E20-1 -> 0 | F21: ='1_Precios'!F21/'1_Precios'!F20-1 -> 0 | G21: ='1_Precios'!G21/'1_Precios'!G20-1 -> 0
A22: ='1_Precios'!A22 -> 0 | B22: ='1_Precios'!B22/'1_Precios'!B21-1 -> 0 | C22: ='1_Precios'!C22/'1_Precios'!C21-1 -> 0 | D22: ='1_Precios'!D22/'1_Precios'!D21-1 -> 0 | E22: ='1_Precios'!E22/'1_Precios'!E21-1 -> 0 | F22: ='1_Precios'!F22/'1_Precios'!F21-1 -> 0 | G22: ='1_Precios'!G22/'1_Precios'!G21-1 -> 0
A23: ='1_Precios'!A23 -> 0 | B23: ='1_Precios'!B23/'1_Precios'!B22-1 -> 0 | C23: ='1_Precios'!C23/'1_Precios'!C22-1 -> 0 | D23: ='1_Precios'!D23/'1_Precios'!D22-1 -> 0 | E23: ='1_Precios'!E23/'1_Precios'!E22-1 -> 0 | F23: ='1_Precios'!F23/'1_Precios'!F22-1 -> 0 | G23: ='1_Precios'!G23/'1_Precios'!G22-1 -> 0
A24: ='1_Precios'!A24 -> 0 | B24: ='1_Precios'!B24/'1_Precios'!B23-1 -> 0 | C24: ='1_Precios'!C24/'1_Precios'!C23-1 -> 0 | D24: ='1_Precios'!D24/'1_Precios'!D23-1 -> 0 | E24: ='1_Precios'!E24/'1_Precios'!E23-1 -> 0 | F24: ='1_Precios'!F24/'1_Precios'!F23-1 -> 0 | G24: ='1_Precios'!G24/'1_Precios'!G23-1 -> 0
A25: ='1_Precios'!A25 -> 0 | B25: ='1_Precios'!B25/'1_Precios'!B24-1 -> 0 | C25: ='1_Precios'!C25/'1_Precios'!C24-1 -> 0 | D25: ='1_Precios'!D25/'1_Precios'!D24-1 -> 0 | E25: ='1_Precios'!E25/'1_Precios'!E24-1 -> 0 | F25: ='1_Precios'!F25/'1_Precios'!F24-1 -> 0 | G25: ='1_Precios'!G25/'1_Precios'!G24-1 -> 0
A26: ='1_Precios'!A26 -> 0 | B26: ='1_Precios'!B26/'1_Precios'!B25-1 -> 0 | C26: ='1_Precios'!C26/'1_Precios'!C25-1 -> 0 | D26: ='1_Precios'!D26/'1_Precios'!D25-1 -> 0 | E26: ='1_Precios'!E26/'1_Precios'!E25-1 -> 0 | F26: ='1_Precios'!F26/'1_Precios'!F25-1 -> 0 | G26: ='1_Precios'!G26/'1_Precios'!G25-1 -> 0
A27: ='1_Precios'!A27 -> 0 | B27: ='1_Precios'!B27/'1_Precios'!B26-1 -> 0 | C27: ='1_Precios'!C27/'1_Precios'!C26-1 -> 0 | D27: ='1_Precios'!D27/'1_Precios'!D26-1 -> 0 | E27: ='1_Precios'!E27/'1_Precios'!E26-1 -> 0 | F27: ='1_Precios'!F27/'1_Precios'!F26-1 -> 0 | G27: ='1_Precios'!G27/'1_Precios'!G26-1 -> 0
A28: ='1_Precios'!A28 -> 0 | B28: ='1_Precios'!B28/'1_Precios'!B27-1 -> 0 | C28: ='1_Precios'!C28/'1_Precios'!C27-1 -> 0 | D28: ='1_Precios'!D28/'1_Precios'!D27-1 -> 0 | E28: ='1_Precios'!E28/'1_Precios'!E27-1 -> 0 | F28: ='1_Precios'!F28/'1_Precios'!F27-1 -> 0 | G28: ='1_Precios'!G28/'1_Precios'!G27-1 -> 0
A29: ='1_Precios'!A29 -> 0 | B29: ='1_Precios'!B29/'1_Precios'!B28-1 -> 0 | C29: ='1_Precios'!C29/'1_Precios'!C28-1 -> 0 | D29: ='1_Precios'!D29/'1_Precios'!D28-1 -> 0 | E29: ='1_Precios'!E29/'1_Precios'!E28-1 -> 0 | F29: ='1_Precios'!F29/'1_Precios'!F28-1 -> 0 | G29: ='1_Precios'!G29/'1_Precios'!G28-1 -> 0
A30: ='1_Precios'!A30 -> 0 | B30: ='1_Precios'!B30/'1_Precios'!B29-1 -> 0 | C30: ='1_Precios'!C30/'1_Precios'!C29-1 -> 0 | D30: ='1_Precios'!D30/'1_Precios'!D29-1 -> 0 | E30: ='1_Precios'!E30/'1_Precios'!E29-1 -> 0 | F30: ='1_Precios'!F30/'1_Precios'!F29-1 -> 0 | G30: ='1_Precios'!G30/'1_Precios'!G29-1 -> 0
A31: ='1_Precios'!A31 -> 0 | B31: ='1_Precios'!B31/'1_Precios'!B30-1 -> 0 | C31: ='1_Precios'!C31/'1_Precios'!C30-1 -> 0 | D31: ='1_Precios'!D31/'1_Precios'!D30-1 -> 0 | E31: ='1_Precios'!E31/'1_Precios'!E30-1 -> 0 | F31: ='1_Precios'!F31/'1_Precios'!F30-1 -> 0 | G31: ='1_Precios'!G31/'1_Precios'!G30-1 -> 0
... A252: ='1_Precios'!A252 -> 0 | B252: ='1_Precios'!B252/'1_Precios'!B251-1 -> 0 | C252: ='1_Precios'!C252/'1_Precios'!C251-1 -> 0 | D252: ='1_Precios'!D252/'1_Precios'!D251-1 -> 0 | E252: ='1_Precios'!E252/'1_Precios'!E251-1 -> 0 | F252: ='1_Precios'!F252/'1_Precios'!F251-1 -> 0 | G252: ='1_Precios'!G252/'1_Precios'!G251-1 -> 0

Sheet 3_Cov_Correl
A1: Matriz de COVARIANZAS anualizadas (x252)
B3: BANCO | C3: RETAIL | D3: MINERA | E3: ENERGIA | F3: CONSUMO | G3: IPSA | I3: Interpretacion
A4: BANCO | B4: =_xlfn.COVARIANCE.S('2_Retornos'!B$2:B$252,'2_Retornos'!B$2:B$252)*'2_Retornos'!$J$3 -> 0 | C4: =_xlfn.COVARIANCE.S('2_Retornos'!B$2:B$252,'2_Retornos'!C$2:C$252)*'2_Retornos'!$J$3 -> 0 | D4: =_xlfn.COVARIANCE.S('2_Retornos'!B$2:B$252,'2_Retornos'!D$2:D$252)*'2_Retornos'!$J$3 -> 0 | E4: =_xlfn.COVARIANCE.S('2_Retornos'!B$2:B$252,'2_Retornos'!E$2:E$252)*'2_Retornos'!$J$3 -> 0 | F4: =_xlfn.COVARIANCE.S('2_Retornos'!B$2:B$252,'2_Retornos'!F$2:F$252)*'2_Retornos'!$J$3 -> 0 | G4: =_xlfn.COVARIANCE.S('2_Retornos'!B$2:B$252,'2_Retornos'!G$2:G$252)*'2_Retornos'!$J$3 -> 0 | I4: Correlacion +1: se mueven igual (no diversifica). 0: independientes. -1: cobertura perfecta.
A5: RETAIL | B5: =_xlfn.COVARIANCE.S('2_Retornos'!C$2:C$252,'2_Retornos'!B$2:B$252)*'2_Retornos'!$J$3 -> 0 | C5: =_xlfn.COVARIANCE.S('2_Retornos'!C$2:C$252,'2_Retornos'!C$2:C$252)*'2_Retornos'!$J$3 -> 0 | D5: =_xlfn.COVARIANCE.S('2_Retornos'!C$2:C$252,'2_Retornos'!D$2:D$252)*'2_Retornos'!$J$3 -> 0 | E5: =_xlfn.COVARIANCE.S('2_Retornos'!C$2:C$252,'2_Retornos'!E$2:E$252)*'2_Retornos'!$J$3 -> 0 | F5: =_xlfn.COVARIANCE.S('2_Retornos'!C$2:C$252,'2_Retornos'!F$2:F$252)*'2_Retornos'!$J$3 -> 0 | G5: =_xlfn.COVARIANCE.S('2_Retornos'!C$2:C$252,'2_Retornos'!G$2:G$252)*'2_Retornos'!$J$3 -> 0 | I5: En Chile las acciones suelen tener correlaciones positivas entre si (todas dependen del ciclo local, el cobre y el dolar).
A6: MINERA | B6: =_xlfn.COVARIANCE.S('2_Retornos'!D$2:D$252,'2_Retornos'!B$2:B$252)*'2_Retornos'!$J$3 -> 0 | C6: =_xlfn.COVARIANCE.S('2_Retornos'!D$2:D$252,'2_Retornos'!C$2:C$252)*'2_Retornos'!$J$3 -> 0 | D6: =_xlfn.COVARIANCE.S('2_Retornos'!D$2:D$252,'2_Retornos'!D$2:D$252)*'2_Retornos'!$J$3 -> 0 | E6: =_xlfn.COVARIANCE.S('2_Retornos'!D$2:D$252,'2_Retornos'!E$2:E$252)*'2_Retornos'!$J$3 -> 0 | F6: =_xlfn.COVARIANCE.S('2_Retornos'!D$2:D$252,'2_Retornos'!F$2:F$252)*'2_Retornos'!$J$3 -> 0 | G6: =_xlfn.COVARIANCE.S('2_Retornos'!D$2:D$252,'2_Retornos'!G$2:G$252)*'2_Retornos'!$J$3 -> 0 | I6: Combinar sectores con correlacion baja (ej. utilities vs mineria) reduce el riesgo de la cartera sin sacrificar retorno esperado.
A7: ENERGIA | B7: =_xlfn.COVARIANCE.S('2_Retornos'!E$2:E$252,'2_Retornos'!B$2:B$252)*'2_Retornos'!$J$3 -> 0 | C7: =_xlfn.COVARIANCE.S('2_Retornos'!E$2:E$252,'2_Retornos'!C$2:C$252)*'2_Retornos'!$J$3 -> 0 | D7: =_xlfn.COVARIANCE.S('2_Retornos'!E$2:E$252,'2_Retornos'!D$2:D$252)*'2_Retornos'!$J$3 -> 0 | E7: =_xlfn.COVARIANCE.S('2_Retornos'!E$2:E$252,'2_Retornos'!E$2:E$252)*'2_Retornos'!$J$3 -> 0 | F7: =_xlfn.COVARIANCE.S('2_Retornos'!E$2:E$252,'2_Retornos'!F$2:F$252)*'2_Retornos'!$J$3 -> 0 | G7: =_xlfn.COVARIANCE.S('2_Retornos'!E$2:E$252,'2_Retornos'!G$2:G$252)*'2_Retornos'!$J$3 -> 0 | I7: Diagonal de la covarianza = varianza de cada activo (volatilidad^2).
A8: CONSUMO | B8: =_xlfn.COVARIANCE.S('2_Retornos'!F$2:F$252,'2_Retornos'!B$2:B$252)*'2_Retornos'!$J$3 -> 0 | C8: =_xlfn.COVARIANCE.S('2_Retornos'!F$2:F$252,'2_Retornos'!C$2:C$252)*'2_Retornos'!$J$3 -> 0 | D8: =_xlfn.COVARIANCE.S('2_Retornos'!F$2:F$252,'2_Retornos'!D$2:D$252)*'2_Retornos'!$J$3 -> 0 | E8: =_xlfn.COVARIANCE.S('2_Retornos'!F$2:F$252,'2_Retornos'!E$2:E$252)*'2_Retornos'!$J$3 -> 0 | F8: =_xlfn.COVARIANCE.S('2_Retornos'!F$2:F$252,'2_Retornos'!F$2:F$252)*'2_Retornos'!$J$3 -> 0 | G8: =_xlfn.COVARIANCE.S('2_Retornos'!F$2:F$252,'2_Retornos'!G$2:G$252)*'2_Retornos'!$J$3 -> 0 | I8: Ojo: las correlaciones cambian en crisis (tienden a subir hacia 1 justo cuando mas necesitas diversificar).
A9: IPSA | B9: =_xlfn.COVARIANCE.S('2_Retornos'!G$2:G$252,'2_Retornos'!B$2:B$252)*'2_Retornos'!$J$3 -> 0 | C9: =_xlfn.COVARIANCE.S('2_Retornos'!G$2:G$252,'2_Retornos'!C$2:C$252)*'2_Retornos'!$J$3 -> 0 | D9: =_xlfn.COVARIANCE.S('2_Retornos'!G$2:G$252,'2_Retornos'!D$2:D$252)*'2_Retornos'!$J$3 -> 0 | E9: =_xlfn.COVARIANCE.S('2_Retornos'!G$2:G$252,'2_Retornos'!E$2:E$252)*'2_Retornos'!$J$3 -> 0 | F9: =_xlfn.COVARIANCE.S('2_Retornos'!G$2:G$252,'2_Retornos'!F$2:F$252)*'2_Retornos'!$J$3 -> 0 | G9: =_xlfn.COVARIANCE.S('2_Retornos'!G$2:G$252,'2_Retornos'!G$2:G$252)*'2_Retornos'!$J$3 -> 0
A11: Matriz de CORRELACIONES
B13: BANCO | C13: RETAIL | D13: MINERA | E13: ENERGIA | F13: CONSUMO | G13: IPSA
A14: BANCO | B14: =CORREL('2_Retornos'!B$2:B$252,'2_Retornos'!B$2:B$252) -> 0 | C14: =CORREL('2_Retornos'!B$2:B$252,'2_Retornos'!C$2:C$252) -> 0 | D14: =CORREL('2_Retornos'!B$2:B$252,'2_Retornos'!D$2:D$252) -> 0 | E14: =CORREL('2_Retornos'!B$2:B$252,'2_Retornos'!E$2:E$252) -> 0 | F14: =CORREL('2_Retornos'!B$2:B$252,'2_Retornos'!F$2:F$252) -> 0 | G14: =CORREL('2_Retornos'!B$2:B$252,'2_Retornos'!G$2:G$252) -> 0
A15: RETAIL | B15: =CORREL('2_Retornos'!C$2:C$252,'2_Retornos'!B$2:B$252) -> 0 | C15: =CORREL('2_Retornos'!C$2:C$252,'2_Retornos'!C$2:C$252) -> 0 | D15: =CORREL('2_Retornos'!C$2:C$252,'2_Retornos'!D$2:D$252) -> 0 | E15: =CORREL('2_Retornos'!C$2:C$252,'2_Retornos'!E$2:E$252) -> 0 | F15: =CORREL('2_Retornos'!C$2:C$252,'2_Retornos'!F$2:F$252) -> 0 | G15: =CORREL('2_Retornos'!C$2:C$252,'2_Retornos'!G$2:G$252) -> 0
A16: MINERA | B16: =CORREL('2_Retornos'!D$2:D$252,'2_Retornos'!B$2:B$252) -> 0 | C16: =CORREL('2_Retornos'!D$2:D$252,'2_Retornos'!C$2:C$252) -> 0 | D16: =CORREL('2_Retornos'!D$2:D$252,'2_Retornos'!D$2:D$252) -> 0 | E16: =CORREL('2_Retornos'!D$2:D$252,'2_Retornos'!E$2:E$252) -> 0 | F16: =CORREL('2_Retornos'!D$2:D$252,'2_Retornos'!F$2:F$252) -> 0 | G16: =CORREL('2_Retornos'!D$2:D$252,'2_Retornos'!G$2:G$252) -> 0
A17: ENERGIA | B17: =CORREL('2_Retornos'!E$2:E$252,'2_Retornos'!B$2:B$252) -> 0 | C17: =CORREL('2_Retornos'!E$2:E$252,'2_Retornos'!C$2:C$252) -> 0 | D17: =CORREL('2_Retornos'!E$2:E$252,'2_Retornos'!D$2:D$252) -> 0 | E17: =CORREL('2_Retornos'!E$2:E$252,'2_Retornos'!E$2:E$252) -> 0 | F17: =CORREL('2_Retornos'!E$2:E$252,'2_Retornos'!F$2:F$252) -> 0 | G17: =CORREL('2_Retornos'!E$2:E$252,'2_Retornos'!G$2:G$252) -> 0
A18: CONSUMO | B18: =CORREL('2_Retornos'!F$2:F$252,'2_Retornos'!B$2:B$252) -> 0 | C18: =CORREL('2_Retornos'!F$2:F$252,'2_Retornos'!C$2:C$252) -> 0 | D18: =CORREL('2_Retornos'!F$2:F$252,'2_Retornos'!D$2:D$252) -> 0 | E18: =CORREL('2_Retornos'!F$2:F$252,'2_Retornos'!E$2:E$252) -> 0 | F18: =CORREL('2_Retornos'!F$2:F$252,'2_Retornos'!F$2:F$252) -> 0 | G18: =CORREL('2_Retornos'!F$2:F$252,'2_Retornos'!G$2:G$252) -> 0
A19: IPSA | B19: =CORREL('2_Retornos'!G$2:G$252,'2_Retornos'!B$2:B$252) -> 0 | C19: =CORREL('2_Retornos'!G$2:G$252,'2_Retornos'!C$2:C$252) -> 0 | D19: =CORREL('2_Retornos'!G$2:G$252,'2_Retornos'!D$2:D$252) -> 0 | E19: =CORREL('2_Retornos'!G$2:G$252,'2_Retornos'!E$2:E$252) -> 0 | F19: =CORREL('2_Retornos'!G$2:G$252,'2_Retornos'!F$2:F$252) -> 0 | G19: =CORREL('2_Retornos'!G$2:G$252,'2_Retornos'!G$2:G$252) -> 0

Sheet 4_Frontera_2A
A1: Frontera eficiente con 2 activos
A2: Cambia las celdas amarillas (sobre todo la correlacion) y observa el grafico.
A4: Retorno esperado activo 1 (E1) | B4: ='2_Retornos'!L7 -> 0 | C4: =MINERA (editable) -> 0
A5: Retorno esperado activo 2 (E2) | B5: ='2_Retornos'!M7 -> 0 | C5: =ENERGIA (editable) -> 0
A6: Volatilidad activo 1 (s1) | B6: ='2_Retornos'!L9 -> 0
A7: Volatilidad activo 2 (s2) | B7: ='2_Retornos'!M9 -> 0
A8: Correlacion (rho) | B8: ='3_Cov_Correl'!E16 -> 0 | C8: Prueba con -1, 0, 0,5 y 1
A10: Peso optimo minima varianza en activo 1 (w1*) | B10: =(B7^2-B8*B6*B7)/(B6^2+B7^2-2*B8*B6*B7) -> 0 | C10: w1* = (s2^2 - rho*s1*s2) / (s1^2 + s2^2 - 2*rho*s1*s2)
A11: Retorno de la cartera de minima varianza | B11: =B10*B4+(1-B10)*B5 -> 0
A12: Volatilidad de la cartera de minima varianza | B12: =SQRT(B10^2*B6^2+(1-B10)^2*B7^2+2*B10*(1-B10)*B8*B6*B7) -> 0
A15: w1 (activo 1) | B15: w2 (activo 2) | C15: Retorno E(Rp) | D15: Volatilidad sp | E15: Sharpe
A16: 0 | B16: =1-A16 -> 0 | C16: =A16*$B$4+B16*$B$5 -> 0 | D16: =SQRT(A16^2*$B$6^2+B16^2*$B$7^2+2*A16*B16*$B$8*$B$6*$B$7) -> 0 | E16: =(C16-'2_Retornos'!$J$2)/D16 -> 0
A17: 0.05 | B17: =1-A17 -> 0 | C17: =A17*$B$4+B17*$B$5 -> 0 | D17: =SQRT(A17^2*$B$6^2+B17^2*$B$7^2+2*A17*B17*$B$8*$B$6*$B$7) -> 0 | E17: =(C17-'2_Retornos'!$J$2)/D17 -> 0
A18: 0.1 | B18: =1-A18 -> 0 | C18: =A18*$B$4+B18*$B$5 -> 0 | D18: =SQRT(A18^2*$B$6^2+B18^2*$B$7^2+2*A18*B18*$B$8*$B$6*$B$7) -> 0 | E18: =(C18-'2_Retornos'!$J$2)/D18 -> 0
A19: 0.15 | B19: =1-A19 -> 0 | C19: =A19*$B$4+B19*$B$5 -> 0 | D19: =SQRT(A19^2*$B$6^2+B19^2*$B$7^2+2*A19*B19*$B$8*$B$6*$B$7) -> 0 | E19: =(C19-'2_Retornos'!$J$2)/D19 -> 0
A20: 0.2 | B20: =1-A20 -> 0 | C20: =A20*$B$4+B20*$B$5 -> 0 | D20: =SQRT(A20^2*$B$6^2+B20^2*$B$7^2+2*A20*B20*$B$8*$B$6*$B$7) -> 0 | E20: =(C20-'2_Retornos'!$J$2)/D20 -> 0
A21: 0.25 | B21: =1-A21 -> 0 | C21: =A21*$B$4+B21*$B$5 -> 0 | D21: =SQRT(A21^2*$B$6^2+B21^2*$B$7^2+2*A21*B21*$B$8*$B$6*$B$7) -> 0 | E21: =(C21-'2_Retornos'!$J$2)/D21 -> 0
A22: 0.3 | B22: =1-A22 -> 0 | C22: =A22*$B$4+B22*$B$5 -> 0 | D22: =SQRT(A22^2*$B$6^2+B22^2*$B$7^2+2*A22*B22*$B$8*$B$6*$B$7) -> 0 | E22: =(C22-'2_Retornos'!$J$2)/D22 -> 0
A23: 0.35 | B23: =1-A23 -> 0 | C23: =A23*$B$4+B23*$B$5 -> 0 | D23: =SQRT(A23^2*$B$6^2+B23^2*$B$7^2+2*A23*B23*$B$8*$B$6*$B$7) -> 0 | E23: =(C23-'2_Retornos'!$J$2)/D23 -> 0
A24: 0.4 | B24: =1-A24 -> 0 | C24: =A24*$B$4+B24*$B$5 -> 0 | D24: =SQRT(A24^2*$B$6^2+B24^2*$B$7^2+2*A24*B24*$B$8*$B$6*$B$7) -> 0 | E24: =(C24-'2_Retornos'!$J$2)/D24 -> 0
A25: 0.45 | B25: =1-A25 -> 0 | C25: =A25*$B$4+B25*$B$5 -> 0 | D25: =SQRT(A25^2*$B$6^2+B25^2*$B$7^2+2*A25*B25*$B$8*$B$6*$B$7) -> 0 | E25: =(C25-'2_Retornos'!$J$2)/D25 -> 0
A26: 0.5 | B26: =1-A26 -> 0 | C26: =A26*$B$4+B26*$B$5 -> 0 | D26: =SQRT(A26^2*$B$6^2+B26^2*$B$7^2+2*A26*B26*$B$8*$B$6*$B$7) -> 0 | E26: =(C26-'2_Retornos'!$J$2)/D26 -> 0 | G26: La parte de la curva SOBRE el punto rojo es la frontera eficiente: mas retorno para cada nivel de riesgo.
A27: 0.55 | B27: =1-A27 -> 0 | C27: =A27*$B$4+B27*$B$5 -> 0 | D27: =SQRT(A27^2*$B$6^2+B27^2*$B$7^2+2*A27*B27*$B$8*$B$6*$B$7) -> 0 | E27: =(C27-'2_Retornos'!$J$2)/D27 -> 0
A28: 0.6 | B28: =1-A28 -> 0 | C28: =A28*$B$4+B28*$B$5 -> 0 | D28: =SQRT(A28^2*$B$6^2+B28^2*$B$7^2+2*A28*B28*$B$8*$B$6*$B$7) -> 0 | E28: =(C28-'2_Retornos'!$J$2)/D28 -> 0
A29: 0.65 | B29: =1-A29 -> 0 | C29: =A29*$B$4+B29*$B$5 -> 0 | D29: =SQRT(A29^2*$B$6^2+B29^2*$B$7^2+2*A29*B29*$B$8*$B$6*$B$7) -> 0 | E29: =(C29-'2_Retornos'!$J$2)/D29 -> 0
A30: 0.7 | B30: =1-A30 -> 0 | C30: =A30*$B$4+B30*$B$5 -> 0 | D30: =SQRT(A30^2*$B$6^2+B30^2*$B$7^2+2*A30*B30*$B$8*$B$6*$B$7) -> 0 | E30: =(C30-'2_Retornos'!$J$2)/D30 -> 0
A31: 0.75 | B31: =1-A31 -> 0 | C31: =A31*$B$4+B31*$B$5 -> 0 | D31: =SQRT(A31^2*$B$6^2+B31^2*$B$7^2+2*A31*B31*$B$8*$B$6*$B$7) -> 0 | E31: =(C31-'2_Retornos'!$J$2)/D31 -> 0
A32: 0.8 | B32: =1-A32 -> 0 | C32: =A32*$B$4+B32*$B$5 -> 0 | D32: =SQRT(A32^2*$B$6^2+B32^2*$B$7^2+2*A32*B32*$B$8*$B$6*$B$7) -> 0 | E32: =(C32-'2_Retornos'!$J$2)/D32 -> 0
A33: 0.85 | B33: =1-A33 -> 0 | C33: =A33*$B$4+B33*$B$5 -> 0 | D33: =SQRT(A33^2*$B$6^2+B33^2*$B$7^2+2*A33*B33*$B$8*$B$6*$B$7) -> 0 | E33: =(C33-'2_Retornos'!$J$2)/D33 -> 0
A34: 0.9 | B34: =1-A34 -> 0 | C34: =A34*$B$4+B34*$B$5 -> 0 | D34: =SQRT(A34^2*$B$6^2+B34^2*$B$7^2+2*A34*B34*$B$8*$B$6*$B$7) -> 0 | E34: =(C34-'2_Retornos'!$J$2)/D34 -> 0
A35: 0.95 | B35: =1-A35 -> 0 | C35: =A35*$B$4+B35*$B$5 -> 0 | D35: =SQRT(A35^2*$B$6^2+B35^2*$B$7^2+2*A35*B35*$B$8*$B$6*$B$7) -> 0 | E35: =(C35-'2_Retornos'!$J$2)/D35 -> 0
A36: 1 | B36: =1-A36 -> 0 | C36: =A36*$B$4+B36*$B$5 -> 0 | D36: =SQRT(A36^2*$B$6^2+B36^2*$B$7^2+2*A36*B36*$B$8*$B$6*$B$7) -> 0 | E36: =(C36-'2_Retornos'!$J$2)/D36 -> 0

Sheet 5_Cartera
A1: Mi cartera de N acciones
A2: Ingresa los pesos (deben sumar 100%). Luego usa Solver para maximizar el Sharpe (ver instrucciones abajo). | I2: Fecha | J2: Ret. cartera | K2: Ret. IPSA | L2: Diferencia | M2: Indice cartera | N2: Drawdown | O2: Indice IPSA
I3: ='2_Retornos'!A2 -> 0 | J3: =SUMPRODUCT($B$5:$F$5,'2_Retornos'!B2:F2) -> 0 | K3: ='2_Retornos'!G2 -> 0 | L3: =J3-K3 -> 0 | M3: =100*(1+J3) -> 0 | N3: =M3/MAX($M$3:M3)-1 -> 0 | O3: =100*(1+K3) -> 0
B4: BANCO | C4: RETAIL | D4: MINERA | E4: ENERGIA | F4: CONSUMO | G4: SUMA | I4: ='2_Retornos'!A3 -> 0 | J4: =SUMPRODUCT($B$5:$F$5,'2_Retornos'!B3:F3) -> 0 | K4: ='2_Retornos'!G3 -> 0 | L4: =J4-K4 -> 0 | M4: =M3*(1+J4) -> 0 | N4: =M4/MAX($M$3:M4)-1 -> 0 | O4: =O3*(1+K4) -> 0
A5: Peso (w) | B5: 0.2 | C5: 0.2 | D5: 0.2 | E5: 0.2 | F5: 0.2 | G5: =SUM(B5:F5) -> 0 | H5: =IF(ROUND(G5,4)<>1,"LOS PESOS NO SUMAN 100%","OK") -> 0 | I5: ='2_Retornos'!A4 -> 0 | J5: =SUMPRODUCT($B$5:$F$5,'2_Retornos'!B4:F4) -> 0 | K5: ='2_Retornos'!G4 -> 0 | L5: =J5-K5 -> 0 | M5: =M4*(1+J5) -> 0 | N5: =M5/MAX($M$3:M5)-1 -> 0 | O5: =O4*(1+K5) -> 0
A6: Retorno anual del activo | B6: ='2_Retornos'!J7 -> 0 | C6: ='2_Retornos'!K7 -> 0 | D6: ='2_Retornos'!L7 -> 0 | E6: ='2_Retornos'!M7 -> 0 | F6: ='2_Retornos'!N7 -> 0 | I6: ='2_Retornos'!A5 -> 0 | J6: =SUMPRODUCT($B$5:$F$5,'2_Retornos'!B5:F5) -> 0 | K6: ='2_Retornos'!G5 -> 0 | L6: =J6-K6 -> 0 | M6: =M5*(1+J6) -> 0 | N6: =M6/MAX($M$3:M6)-1 -> 0 | O6: =O5*(1+K6) -> 0
A7: Volatilidad anual del activo | B7: ='2_Retornos'!J9 -> 0 | C7: ='2_Retornos'!K9 -> 0 | D7: ='2_Retornos'!L9 -> 0 | E7: ='2_Retornos'!M9 -> 0 | F7: ='2_Retornos'!N9 -> 0 | I7: ='2_Retornos'!A6 -> 0 | J7: =SUMPRODUCT($B$5:$F$5,'2_Retornos'!B6:F6) -> 0 | K7: ='2_Retornos'!G6 -> 0 | L7: =J7-K7 -> 0 | M7: =M6*(1+J7) -> 0 | N7: =M7/MAX($M$3:M7)-1 -> 0 | O7: =O6*(1+K7) -> 0
I8: ='2_Retornos'!A7 -> 0 | J8: =SUMPRODUCT($B$5:$F$5,'2_Retornos'!B7:F7) -> 0 | K8: ='2_Retornos'!G7 -> 0 | L8: =J8-K8 -> 0 | M8: =M7*(1+J8) -> 0 | N8: =M8/MAX($M$3:M8)-1 -> 0 | O8: =O7*(1+K8) -> 0
A9: Retorno anual de la cartera | B9: =(1+AVERAGE(J3:J253))^'2_Retornos'!$J$3-1 -> 0 | I9: ='2_Retornos'!A8 -> 0 | J9: =SUMPRODUCT($B$5:$F$5,'2_Retornos'!B8:F8) -> 0 | K9: ='2_Retornos'!G8 -> 0 | L9: =J9-K9 -> 0 | M9: =M8*(1+J9) -> 0 | N9: =M9/MAX($M$3:M9)-1 -> 0 | O9: =O8*(1+K9) -> 0
A10: Volatilidad anual de la cartera | B10: =_xlfn.STDEV.S(J3:J253)*SQRT('2_Retornos'!$J$3) -> 0 | I10: ='2_Retornos'!A9 -> 0 | J10: =SUMPRODUCT($B$5:$F$5,'2_Retornos'!B9:F9) -> 0 | K10: ='2_Retornos'!G9 -> 0 | L10: =J10-K10 -> 0 | M10: =M9*(1+J10) -> 0 | N10: =M10/MAX($M$3:M10)-1 -> 0 | O10: =O9*(1+K10) -> 0
A11: Ratio de Sharpe | B11: =(B9-'2_Retornos'!$J$2)/B10 -> 0 | C11: Retorno extra por unidad de riesgo total | I11: ='2_Retornos'!A10 -> 0 | J11: =SUMPRODUCT($B$5:$F$5,'2_Retornos'!B10:F10) -> 0 | K11: ='2_Retornos'!G10 -> 0 | L11: =J11-K11 -> 0 | M11: =M10*(1+J11) -> 0 | N11: =M11/MAX($M$3:M11)-1 -> 0 | O11: =O10*(1+K11) -> 0
A12: Beta de la cartera vs IPSA | B12: =SLOPE(J3:J253,K3:K253) -> 0 | C12: >1 mas agresiva que el mercado; <1 mas defensiva | I12: ='2_Retornos'!A11 -> 0 | J12: =SUMPRODUCT($B$5:$F$5,'2_Retornos'!B11:F11) -> 0 | K12: ='2_Retornos'!G11 -> 0 | L12: =J12-K12 -> 0 | M12: =M11*(1+J12) -> 0 | N12: =M12/MAX($M$3:M12)-1 -> 0 | O12: =O11*(1+K12) -> 0
A13: Ratio de Treynor | B13: =(B9-'2_Retornos'!$J$2)/B12 -> 0 | I13: ='2_Retornos'!A12 -> 0 | J13: =SUMPRODUCT($B$5:$F$5,'2_Retornos'!B12:F12) -> 0 | K13: ='2_Retornos'!G12 -> 0 | L13: =J13-K13 -> 0 | M13: =M12*(1+J13) -> 0 | N13: =M13/MAX($M$3:M13)-1 -> 0 | O13: =O12*(1+K13) -> 0
A14: Retorno anual IPSA | B14: ='2_Retornos'!O7 -> 0 | I14: ='2_Retornos'!A13 -> 0 | J14: =SUMPRODUCT($B$5:$F$5,'2_Retornos'!B13:F13) -> 0 | K14: ='2_Retornos'!G13 -> 0 | L14: =J14-K14 -> 0 | M14: =M13*(1+J14) -> 0 | N14: =M14/MAX($M$3:M14)-1 -> 0 | O14: =O13*(1+K14) -> 0
A15: Alfa de Jensen (anual) | B15: =B9-('2_Retornos'!$J$2+B12*(B14-'2_Retornos'!$J$2)) -> 0 | C15: Retorno sobre lo que exige el CAPM dado su beta | I15: ='2_Retornos'!A14 -> 0 | J15: =SUMPRODUCT($B$5:$F$5,'2_Retornos'!B14:F14) -> 0 | K15: ='2_Retornos'!G14 -> 0 | L15: =J15-K15 -> 0 | M15: =M14*(1+J15) -> 0 | N15: =M15/MAX($M$3:M15)-1 -> 0 | O15: =O14*(1+K15) -> 0
A16: Tracking error vs IPSA | B16: =_xlfn.STDEV.S(L3:L253)*SQRT('2_Retornos'!$J$3) -> 0 | I16: ='2_Retornos'!A15 -> 0 | J16: =SUMPRODUCT($B$5:$F$5,'2_Retornos'!B15:F15) -> 0 | K16: ='2_Retornos'!G15 -> 0 | L16: =J16-K16 -> 0 | M16: =M15*(1+J16) -> 0 | N16: =M16/MAX($M$3:M16)-1 -> 0 | O16: =O15*(1+K16) -> 0
A17: Information ratio | B17: =(B9-B14)/B16 -> 0 | I17: ='2_Retornos'!A16 -> 0 | J17: =SUMPRODUCT($B$5:$F$5,'2_Retornos'!B16:F16) -> 0 | K17: ='2_Retornos'!G16 -> 0 | L17: =J17-K17 -> 0 | M17: =M16*(1+J17) -> 0 | N17: =M17/MAX($M$3:M17)-1 -> 0 | O17: =O16*(1+K17) -> 0
A18: Volatilidad promedio ponderada (sin diversificar) | B18: =SUMPRODUCT(B5:F5,B7:F7) -> 0 | I18: ='2_Retornos'!A17 -> 0 | J18: =SUMPRODUCT($B$5:$F$5,'2_Retornos'!B17:F17) -> 0 | K18: ='2_Retornos'!G17 -> 0 | L18: =J18-K18 -> 0 | M18: =M17*(1+J18) -> 0 | N18: =M18/MAX($M$3:M18)-1 -> 0 | O18: =O17*(1+K18) -> 0
A19: Reduccion de riesgo por diversificacion | B19: =1-B10/B18 -> 0 | C19: Cuanto riesgo "gratis" eliminaste combinando acciones | I19: ='2_Retornos'!A18 -> 0 | J19: =SUMPRODUCT($B$5:$F$5,'2_Retornos'!B18:F18) -> 0 | K19: ='2_Retornos'!G18 -> 0 | L19: =J19-K19 -> 0 | M19: =M18*(1+J19) -> 0 | N19: =M19/MAX($M$3:M19)-1 -> 0 | O19: =O18*(1+K19) -> 0
A20: Max. drawdown de la cartera | B20: =MIN(N3:N253) -> 0 | I20: ='2_Retornos'!A19 -> 0 | J20: =SUMPRODUCT($B$5:$F$5,'2_Retornos'!B19:F19) -> 0 | K20: ='2_Retornos'!G19 -> 0 | L20: =J20-K20 -> 0 | M20: =M19*(1+J20) -> 0 | N20: =M20/MAX($M$3:M20)-1 -> 0 | O20: =O19*(1+K20) -> 0
I21: ='2_Retornos'!A20 -> 0 | J21: =SUMPRODUCT($B$5:$F$5,'2_Retornos'!B20:F20) -> 0 | K21: ='2_Retornos'!G20 -> 0 | L21: =J21-K21 -> 0 | M21: =M20*(1+J21) -> 0 | N21: =M21/MAX($M$3:M21)-1 -> 0 | O21: =O20*(1+K21) -> 0
A22: SOLVER (Datos > Solver; si no aparece: Archivo > Opciones > Complementos > Solver): | I22: ='2_Retornos'!A21 -> 0 | J22: =SUMPRODUCT($B$5:$F$5,'2_Retornos'!B21:F21) -> 0 | K22: ='2_Retornos'!G21 -> 0 | L22: =J22-K22 -> 0 | M22: =M21*(1+J22) -> 0 | N22: =M22/MAX($M$3:M22)-1 -> 0 | O22: =O21*(1+K22) -> 0
A23: Establecer objetivo: $B$11 (Sharpe) -> Max | I23: ='2_Retornos'!A22 -> 0 | J23: =SUMPRODUCT($B$5:$F$5,'2_Retornos'!B22:F22) -> 0 | K23: ='2_Retornos'!G22 -> 0 | L23: =J23-K23 -> 0 | M23: =M22*(1+J23) -> 0 | N23: =M23/MAX($M$3:M23)-1 -> 0 | O23: =O22*(1+K23) -> 0
A24: Cambiando las celdas: $B$5:$F$5 | I24: ='2_Retornos'!A23 -> 0 | J24: =SUMPRODUCT($B$5:$F$5,'2_Retornos'!B23:F23) -> 0 | K24: ='2_Retornos'!G23 -> 0 | L24: =J24-K24 -> 0 | M24: =M23*(1+J24) -> 0 | N24: =M24/MAX($M$3:M24)-1 -> 0 | O24: =O23*(1+K24) -> 0
A25: Restricciones: $G$5 = 1 y $B$5:$F$5 >= 0 (sin ventas cortas). Opcional: $B$5:$F$5 <= 0,35 (limite por accion) | I25: ='2_Retornos'!A24 -> 0 | J25: =SUMPRODUCT($B$5:$F$5,'2_Retornos'!B24:F24) -> 0 | K25: ='2_Retornos'!G24 -> 0 | L25: =J25-K25 -> 0 | M25: =M24*(1+J25) -> 0 | N25: =M25/MAX($M$3:M25)-1 -> 0 | O25: =O24*(1+K25) -> 0
A26: Metodo: GRG Nonlinear. Repite con objetivo $B$10 -> Min para la cartera de minima varianza. | I26: ='2_Retornos'!A25 -> 0 | J26: =SUMPRODUCT($B$5:$F$5,'2_Retornos'!B25:F25) -> 0 | K26: ='2_Retornos'!G25 -> 0 | L26: =J26-K26 -> 0 | M26: =M25*(1+J26) -> 0 | N26: =M26/MAX($M$3:M26)-1 -> 0 | O26: =O25*(1+K26) -> 0
I27: ='2_Retornos'!A26 -> 0 | J27: =SUMPRODUCT($B$5:$F$5,'2_Retornos'!B26:F26) -> 0 | K27: ='2_Retornos'!G26 -> 0 | L27: =J27-K27 -> 0 | M27: =M26*(1+J27) -> 0 | N27: =M27/MAX($M$3:M27)-1 -> 0 | O27: =O26*(1+K27) -> 0
I28: ='2_Retornos'!A27 -> 0 | J28: =SUMPRODUCT($B$5:$F$5,'2_Retornos'!B27:F27) -> 0 | K28: ='2_Retornos'!G27 -> 0 | L28: =J28-K28 -> 0 | M28: =M27*(1+J28) -> 0 | N28: =M28/MAX($M$3:M28)-1 -> 0 | O28: =O27*(1+K28) -> 0
I29: ='2_Retornos'!A28 -> 0 | J29: =SUMPRODUCT($B$5:$F$5,'2_Retornos'!B28:F28) -> 0 | K29: ='2_Retornos'!G28 -> 0 | L29: =J29-K29 -> 0 | M29: =M28*(1+J29) -> 0 | N29: =M29/MAX($M$3:M29)-1 -> 0 | O29: =O28*(1+K29) -> 0
I30: ='2_Retornos'!A29 -> 0 | J30: =SUMPRODUCT($B$5:$F$5,'2_Retornos'!B29:F29) -> 0 | K30: ='2_Retornos'!G29 -> 0 | L30: =J30-K30 -> 0 | M30: =M29*(1+J30) -> 0 | N30: =M30/MAX($M$3:M30)-1 -> 0 | O30: =O29*(1+K30) -> 0
I31: ='2_Retornos'!A30 -> 0 | J31: =SUMPRODUCT($B$5:$F$5,'2_Retornos'!B30:F30) -> 0 | K31: ='2_Retornos'!G30 -> 0 | L31: =J31-K31 -> 0 | M31: =M30*(1+J31) -> 0 | N31: =M31/MAX($M$3:M31)-1 -> 0 | O31: =O30*(1+K31) -> 0
I32: ='2_Retornos'!A31 -> 0 | J32: =SUMPRODUCT($B$5:$F$5,'2_Retornos'!B31:F31) -> 0 | K32: ='2_Retornos'!G31 -> 0 | L32: =J32-K32 -> 0 | M32: =M31*(1+J32) -> 0 | N32: =M32/MAX($M$3:M32)-1 -> 0 | O32: =O31*(1+K32) -> 0
I33: ='2_Retornos'!A32 -> 0 | J33: =SUMPRODUCT($B$5:$F$5,'2_Retornos'!B32:F32) -> 0 | K33: ='2_Retornos'!G32 -> 0 | L33: =J33-K33 -> 0 | M33: =M32*(1+J33) -> 0 | N33: =M33/MAX($M$3:M33)-1 -> 0 | O33: =O32*(1+K33) -> 0
I34: ='2_Retornos'!A33 -> 0 | J34: =SUMPRODUCT($B$5:$F$5,'2_Retornos'!B33:F33) -> 0 | K34: ='2_Retornos'!G33 -> 0 | L34: =J34-K34 -> 0 | M34: =M33*(1+J34) -> 0 | N34: =M34/MAX($M$3:M34)-1 -> 0 | O34: =O33*(1+K34) -> 0
I35: ='2_Retornos'!A34 -> 0 | J35: =SUMPRODUCT($B$5:$F$5,'2_Retornos'!B34:F34) -> 0 | K35: ='2_Retornos'!G34 -> 0 | L35: =J35-K35 -> 0 | M35: =M34*(1+J35) -> 0 | N35: =M35/MAX($M$3:M35)-1 -> 0 | O35: =O34*(1+K35) -> 0
I36: ='2_Retornos'!A35 -> 0 | J36: =SUMPRODUCT($B$5:$F$5,'2_Retornos'!B35:F35) -> 0 | K36: ='2_Retornos'!G35 -> 0 | L36: =J36-K36 -> 0 | M36: =M35*(1+J36) -> 0 | N36: =M36/MAX($M$3:M36)-1 -> 0 | O36: =O35*(1+K36) -> 0
I37: ='2_Retornos'!A36 -> 0 | J37: =SUMPRODUCT($B$5:$F$5,'2_Retornos'!B36:F36) -> 0 | K37: ='2_Retornos'!G36 -> 0 | L37: =J37-K37 -> 0 | M37: =M36*(1+J37) -> 0 | N37: =M37/MAX($M$3:M37)-1 -> 0 | O37: =O36*(1+K37) -> 0
I38: ='2_Retornos'!A37 -> 0 | J38: =SUMPRODUCT($B$5:$F$5,'2_Retornos'!B37:F37) -> 0 | K38: ='2_Retornos'!G37 -> 0 | L38: =J38-K38 -> 0 | M38: =M37*(1+J38) -> 0 | N38: =M38/MAX($M$3:M38)-1 -> 0 | O38: =O37*(1+K38) -> 0
... I253: ='2_Retornos'!A252 -> 0 | J253: =SUMPRODUCT($B$5:$F$5,'2_Retornos'!B252:F252) -> 0 | K253: ='2_Retornos'!G252 -> 0 | L253: =J253-K253 -> 0 | M253: =M252*(1+J253) -> 0 | N253: =M253/MAX($M$3:M253)-1 -> 0 | O253: =O252*(1+K253) -> 0

Sheet 6_Beta_CAPM
A1: Beta y CAPM
A3: Tasa libre de riesgo anual (rf) | B3: ='2_Retornos'!J2 -> 0
A4: Prima por riesgo de mercado (ERP) | B4: 0.0533 | C4: Ej.: prima total Chile Damodaran ene-2026 (verificar). Editable.
A7: Metrica | B7: BANCO | C7: RETAIL | D7: MINERA | E7: ENERGIA | F7: CONSUMO
A8: Beta (pendiente vs IPSA) | B8: =SLOPE('2_Retornos'!B$2:B$252,'2_Retornos'!$G$2:$G$252) -> 0 | C8: =SLOPE('2_Retornos'!C$2:C$252,'2_Retornos'!$G$2:$G$252) -> 0 | D8: =SLOPE('2_Retornos'!D$2:D$252,'2_Retornos'!$G$2:$G$252) -> 0 | E8: =SLOPE('2_Retornos'!E$2:E$252,'2_Retornos'!$G$2:$G$252) -> 0 | F8: =SLOPE('2_Retornos'!F$2:F$252,'2_Retornos'!$G$2:$G$252) -> 0
A9: R2 (riesgo explicado por el mercado) | B9: =RSQ('2_Retornos'!B$2:B$252,'2_Retornos'!$G$2:$G$252) -> 0 | C9: =RSQ('2_Retornos'!C$2:C$252,'2_Retornos'!$G$2:$G$252) -> 0 | D9: =RSQ('2_Retornos'!D$2:D$252,'2_Retornos'!$G$2:$G$252) -> 0 | E9: =RSQ('2_Retornos'!E$2:E$252,'2_Retornos'!$G$2:$G$252) -> 0 | F9: =RSQ('2_Retornos'!F$2:F$252,'2_Retornos'!$G$2:$G$252) -> 0
A10: Riesgo idiosincratico (1 - R2) | B10: =1-B9 -> 0 | C10: =1-C9 -> 0 | D10: =1-D9 -> 0 | E10: =1-E9 -> 0 | F10: =1-F9 -> 0
A11: Alfa diario (intercepto) | B11: =INTERCEPT('2_Retornos'!B$2:B$252,'2_Retornos'!$G$2:$G$252) -> 0 | C11: =INTERCEPT('2_Retornos'!C$2:C$252,'2_Retornos'!$G$2:$G$252) -> 0 | D11: =INTERCEPT('2_Retornos'!D$2:D$252,'2_Retornos'!$G$2:$G$252) -> 0 | E11: =INTERCEPT('2_Retornos'!E$2:E$252,'2_Retornos'!$G$2:$G$252) -> 0 | F11: =INTERCEPT('2_Retornos'!F$2:F$252,'2_Retornos'!$G$2:$G$252) -> 0
A12: Retorno exigido CAPM: rf + beta x ERP | B12: =$B$3+B8*$B$4 -> 0 | C12: =$B$3+C8*$B$4 -> 0 | D12: =$B$3+D8*$B$4 -> 0 | E12: =$B$3+E8*$B$4 -> 0 | F12: =$B$3+F8*$B$4 -> 0
A13: Retorno observado anual | B13: ='2_Retornos'!J7 -> 0 | C13: ='2_Retornos'!K7 -> 0 | D13: ='2_Retornos'!L7 -> 0 | E13: ='2_Retornos'!M7 -> 0 | F13: ='2_Retornos'!N7 -> 0
A14: Diferencia (observado - CAPM) | B14: =B13-B12 -> 0 | C14: =C13-C12 -> 0 | D14: =D13-D12 -> 0 | E14: =E13-E12 -> 0 | F14: =F13-F12 -> 0
A16: Lectura: beta 1,4 => si el IPSA sube 1%, la accion tiende a subir 1,4%. En un torneo, las betas altas amplifican el resultado (para bien y para mal).

Sheet 7_Tecnico
A1: Accion: | B1: MINERA | C1: <- elige la accion (lista desplegable) | E1: Ultima senal: | F1: =IFERROR(LOOKUP(2,1/(E4:E255<>""),E4:E255),"sin senal") -> 0 | H1: ="RSI actual: "&TEXT(H255,"0.0")&IF(H255>70," (sobrecompra)",IF(H255<30," (sobreventa)","")) -> 0
A3: Fecha | B3: Precio | C3: SMA 20 | D3: SMA 50 | E3: Senal cruce | F3: Ganancia | G3: Perdida | H3: RSI 14 | I3: Bollinger sup | J3: Bollinger inf
A4: ='1_Precios'!A2 -> 0 | B4: =INDEX('1_Precios'!$B$2:$F$2,MATCH($B$1,'1_Precios'!$B$1:$F$1,0)) -> 0
A5: ='1_Precios'!A3 -> 0 | B5: =INDEX('1_Precios'!$B$3:$F$3,MATCH($B$1,'1_Precios'!$B$1:$F$1,0)) -> 0 | F5: =MAX(B5-B4,0) -> 0 | G5: =MAX(B4-B5,0) -> 0
A6: ='1_Precios'!A4 -> 0 | B6: =INDEX('1_Precios'!$B$4:$F$4,MATCH($B$1,'1_Precios'!$B$1:$F$1,0)) -> 0 | F6: =MAX(B6-B5,0) -> 0 | G6: =MAX(B5-B6,0) -> 0
A7: ='1_Precios'!A5 -> 0 | B7: =INDEX('1_Precios'!$B$5:$F$5,MATCH($B$1,'1_Precios'!$B$1:$F$1,0)) -> 0 | F7: =MAX(B7-B6,0) -> 0 | G7: =MAX(B6-B7,0) -> 0
A8: ='1_Precios'!A6 -> 0 | B8: =INDEX('1_Precios'!$B$6:$F$6,MATCH($B$1,'1_Precios'!$B$1:$F$1,0)) -> 0 | F8: =MAX(B8-B7,0) -> 0 | G8: =MAX(B7-B8,0) -> 0
A9: ='1_Precios'!A7 -> 0 | B9: =INDEX('1_Precios'!$B$7:$F$7,MATCH($B$1,'1_Precios'!$B$1:$F$1,0)) -> 0 | F9: =MAX(B9-B8,0) -> 0 | G9: =MAX(B8-B9,0) -> 0
A10: ='1_Precios'!A8 -> 0 | B10: =INDEX('1_Precios'!$B$8:$F$8,MATCH($B$1,'1_Precios'!$B$1:$F$1,0)) -> 0 | F10: =MAX(B10-B9,0) -> 0 | G10: =MAX(B9-B10,0) -> 0
A11: ='1_Precios'!A9 -> 0 | B11: =INDEX('1_Precios'!$B$9:$F$9,MATCH($B$1,'1_Precios'!$B$1:$F$1,0)) -> 0 | F11: =MAX(B11-B10,0) -> 0 | G11: =MAX(B10-B11,0) -> 0
A12: ='1_Precios'!A10 -> 0 | B12: =INDEX('1_Precios'!$B$10:$F$10,MATCH($B$1,'1_Precios'!$B$1:$F$1,0)) -> 0 | F12: =MAX(B12-B11,0) -> 0 | G12: =MAX(B11-B12,0) -> 0
A13: ='1_Precios'!A11 -> 0 | B13: =INDEX('1_Precios'!$B$11:$F$11,MATCH($B$1,'1_Precios'!$B$1:$F$1,0)) -> 0 | F13: =MAX(B13-B12,0) -> 0 | G13: =MAX(B12-B13,0) -> 0
A14: ='1_Precios'!A12 -> 0 | B14: =INDEX('1_Precios'!$B$12:$F$12,MATCH($B$1,'1_Precios'!$B$1:$F$1,0)) -> 0 | F14: =MAX(B14-B13,0) -> 0 | G14: =MAX(B13-B14,0) -> 0
A15: ='1_Precios'!A13 -> 0 | B15: =INDEX('1_Precios'!$B$13:$F$13,MATCH($B$1,'1_Precios'!$B$1:$F$1,0)) -> 0 | F15: =MAX(B15-B14,0) -> 0 | G15: =MAX(B14-B15,0) -> 0
A16: ='1_Precios'!A14 -> 0 | B16: =INDEX('1_Precios'!$B$14:$F$14,MATCH($B$1,'1_Precios'!$B$1:$F$1,0)) -> 0 | F16: =MAX(B16-B15,0) -> 0 | G16: =MAX(B15-B16,0) -> 0
A17: ='1_Precios'!A15 -> 0 | B17: =INDEX('1_Precios'!$B$15:$F$15,MATCH($B$1,'1_Precios'!$B$1:$F$1,0)) -> 0 | F17: =MAX(B17-B16,0) -> 0 | G17: =MAX(B16-B17,0) -> 0
A18: ='1_Precios'!A16 -> 0 | B18: =INDEX('1_Precios'!$B$16:$F$16,MATCH($B$1,'1_Precios'!$B$1:$F$1,0)) -> 0 | F18: =MAX(B18-B17,0) -> 0 | G18: =MAX(B17-B18,0) -> 0 | H18: =IF(SUM(G5:G18)=0,100,100-100/(1+AVERAGE(F5:F18)/AVERAGE(G5:G18))) -> 0
A19: ='1_Precios'!A17 -> 0 | B19: =INDEX('1_Precios'!$B$17:$F$17,MATCH($B$1,'1_Precios'!$B$1:$F$1,0)) -> 0 | F19: =MAX(B19-B18,0) -> 0 | G19: =MAX(B18-B19,0) -> 0 | H19: =IF(SUM(G6:G19)=0,100,100-100/(1+AVERAGE(F6:F19)/AVERAGE(G6:G19))) -> 0
A20: ='1_Precios'!A18 -> 0 | B20: =INDEX('1_Precios'!$B$18:$F$18,MATCH($B$1,'1_Precios'!$B$1:$F$1,0)) -> 0 | F20: =MAX(B20-B19,0) -> 0 | G20: =MAX(B19-B20,0) -> 0 | H20: =IF(SUM(G7:G20)=0,100,100-100/(1+AVERAGE(F7:F20)/AVERAGE(G7:G20))) -> 0
A21: ='1_Precios'!A19 -> 0 | B21: =INDEX('1_Precios'!$B$19:$F$19,MATCH($B$1,'1_Precios'!$B$1:$F$1,0)) -> 0 | F21: =MAX(B21-B20,0) -> 0 | G21: =MAX(B20-B21,0) -> 0 | H21: =IF(SUM(G8:G21)=0,100,100-100/(1+AVERAGE(F8:F21)/AVERAGE(G8:G21))) -> 0
A22: ='1_Precios'!A20 -> 0 | B22: =INDEX('1_Precios'!$B$20:$F$20,MATCH($B$1,'1_Precios'!$B$1:$F$1,0)) -> 0 | F22: =MAX(B22-B21,0) -> 0 | G22: =MAX(B21-B22,0) -> 0 | H22: =IF(SUM(G9:G22)=0,100,100-100/(1+AVERAGE(F9:F22)/AVERAGE(G9:G22))) -> 0
A23: ='1_Precios'!A21 -> 0 | B23: =INDEX('1_Precios'!$B$21:$F$21,MATCH($B$1,'1_Precios'!$B$1:$F$1,0)) -> 0 | C23: =AVERAGE(B4:B23) -> 0 | F23: =MAX(B23-B22,0) -> 0 | G23: =MAX(B22-B23,0) -> 0 | H23: =IF(SUM(G10:G23)=0,100,100-100/(1+AVERAGE(F10:F23)/AVERAGE(G10:G23))) -> 0 | I23: =C23+2*_xlfn.STDEV.S(B4:B23) -> 0 | J23: =C23-2*_xlfn.STDEV.S(B4:B23) -> 0
A24: ='1_Precios'!A22 -> 0 | B24: =INDEX('1_Precios'!$B$22:$F$22,MATCH($B$1,'1_Precios'!$B$1:$F$1,0)) -> 0 | C24: =AVERAGE(B5:B24) -> 0 | F24: =MAX(B24-B23,0) -> 0 | G24: =MAX(B23-B24,0) -> 0 | H24: =IF(SUM(G11:G24)=0,100,100-100/(1+AVERAGE(F11:F24)/AVERAGE(G11:G24))) -> 0 | I24: =C24+2*_xlfn.STDEV.S(B5:B24) -> 0 | J24: =C24-2*_xlfn.STDEV.S(B5:B24) -> 0
A25: ='1_Precios'!A23 -> 0 | B25: =INDEX('1_Precios'!$B$23:$F$23,MATCH($B$1,'1_Precios'!$B$1:$F$1,0)) -> 0 | C25: =AVERAGE(B6:B25) -> 0 | F25: =MAX(B25-B24,0) -> 0 | G25: =MAX(B24-B25,0) -> 0 | H25: =IF(SUM(G12:G25)=0,100,100-100/(1+AVERAGE(F12:F25)/AVERAGE(G12:G25))) -> 0 | I25: =C25+2*_xlfn.STDEV.S(B6:B25) -> 0 | J25: =C25-2*_xlfn.STDEV.S(B6:B25) -> 0
A26: ='1_Precios'!A24 -> 0 | B26: =INDEX('1_Precios'!$B$24:$F$24,MATCH($B$1,'1_Precios'!$B$1:$F$1,0)) -> 0 | C26: =AVERAGE(B7:B26) -> 0 | F26: =MAX(B26-B25,0) -> 0 | G26: =MAX(B25-B26,0) -> 0 | H26: =IF(SUM(G13:G26)=0,100,100-100/(1+AVERAGE(F13:F26)/AVERAGE(G13:G26))) -> 0 | I26: =C26+2*_xlfn.STDEV.S(B7:B26) -> 0 | J26: =C26-2*_xlfn.STDEV.S(B7:B26) -> 0
A27: ='1_Precios'!A25 -> 0 | B27: =INDEX('1_Precios'!$B$25:$F$25,MATCH($B$1,'1_Precios'!$B$1:$F$1,0)) -> 0 | C27: =AVERAGE(B8:B27) -> 0 | F27: =MAX(B27-B26,0) -> 0 | G27: =MAX(B26-B27,0) -> 0 | H27: =IF(SUM(G14:G27)=0,100,100-100/(1+AVERAGE(F14:F27)/AVERAGE(G14:G27))) -> 0 | I27: =C27+2*_xlfn.STDEV.S(B8:B27) -> 0 | J27: =C27-2*_xlfn.STDEV.S(B8:B27) -> 0
A28: ='1_Precios'!A26 -> 0 | B28: =INDEX('1_Precios'!$B$26:$F$26,MATCH($B$1,'1_Precios'!$B$1:$F$1,0)) -> 0 | C28: =AVERAGE(B9:B28) -> 0 | F28: =MAX(B28-B27,0) -> 0 | G28: =MAX(B27-B28,0) -> 0 | H28: =IF(SUM(G15:G28)=0,100,100-100/(1+AVERAGE(F15:F28)/AVERAGE(G15:G28))) -> 0 | I28: =C28+2*_xlfn.STDEV.S(B9:B28) -> 0 | J28: =C28-2*_xlfn.STDEV.S(B9:B28) -> 0
A29: ='1_Precios'!A27 -> 0 | B29: =INDEX('1_Precios'!$B$27:$F$27,MATCH($B$1,'1_Precios'!$B$1:$F$1,0)) -> 0 | C29: =AVERAGE(B10:B29) -> 0 | F29: =MAX(B29-B28,0) -> 0 | G29: =MAX(B28-B29,0) -> 0 | H29: =IF(SUM(G16:G29)=0,100,100-100/(1+AVERAGE(F16:F29)/AVERAGE(G16:G29))) -> 0 | I29: =C29+2*_xlfn.STDEV.S(B10:B29) -> 0 | J29: =C29-2*_xlfn.STDEV.S(B10:B29) -> 0
A30: ='1_Precios'!A28 -> 0 | B30: =INDEX('1_Precios'!$B$28:$F$28,MATCH($B$1,'1_Precios'!$B$1:$F$1,0)) -> 0 | C30: =AVERAGE(B11:B30) -> 0 | F30: =MAX(B30-B29,0) -> 0 | G30: =MAX(B29-B30,0) -> 0 | H30: =IF(SUM(G17:G30)=0,100,100-100/(1+AVERAGE(F17:F30)/AVERAGE(G17:G30))) -> 0 | I30: =C30+2*_xlfn.STDEV.S(B11:B30) -> 0 | J30: =C30-2*_xlfn.STDEV.S(B11:B30) -> 0
A31: ='1_Precios'!A29 -> 0 | B31: =INDEX('1_Precios'!$B$29:$F$29,MATCH($B$1,'1_Precios'!$B$1:$F$1,0)) -> 0 | C31: =AVERAGE(B12:B31) -> 0 | F31: =MAX(B31-B30,0) -> 0 | G31: =MAX(B30-B31,0) -> 0 | H31: =IF(SUM(G18:G31)=0,100,100-100/(1+AVERAGE(F18:F31)/AVERAGE(G18:G31))) -> 0 | I31: =C31+2*_xlfn.STDEV.S(B12:B31) -> 0 | J31: =C31-2*_xlfn.STDEV.S(B12:B31) -> 0
A32: ='1_Precios'!A30 -> 0 | B32: =INDEX('1_Precios'!$B$30:$F$30,MATCH($B$1,'1_Precios'!$B$1:$F$1,0)) -> 0 | C32: =AVERAGE(B13:B32) -> 0 | F32: =MAX(B32-B31,0) -> 0 | G32: =MAX(B31-B32,0) -> 0 | H32: =IF(SUM(G19:G32)=0,100,100-100/(1+AVERAGE(F19:F32)/AVERAGE(G19:G32))) -> 0 | I32: =C32+2*_xlfn.STDEV.S(B13:B32) -> 0 | J32: =C32-2*_xlfn.STDEV.S(B13:B32) -> 0
A33: ='1_Precios'!A31 -> 0 | B33: =INDEX('1_Precios'!$B$31:$F$31,MATCH($B$1,'1_Precios'!$B$1:$F$1,0)) -> 0 | C33: =AVERAGE(B14:B33) -> 0 | F33: =MAX(B33-B32,0) -> 0 | G33: =MAX(B32-B33,0) -> 0 | H33: =IF(SUM(G20:G33)=0,100,100-100/(1+AVERAGE(F20:F33)/AVERAGE(G20:G33))) -> 0 | I33: =C33+2*_xlfn.STDEV.S(B14:B33) -> 0 | J33: =C33-2*_xlfn.STDEV.S(B14:B33) -> 0
A34: ='1_Precios'!A32 -> 0 | B34: =INDEX('1_Precios'!$B$32:$F$32,MATCH($B$1,'1_Precios'!$B$1:$F$1,0)) -> 0 | C34: =AVERAGE(B15:B34) -> 0 | F34: =MAX(B34-B33,0) -> 0 | G34: =MAX(B33-B34,0) -> 0 | H34: =IF(SUM(G21:G34)=0,100,100-100/(1+AVERAGE(F21:F34)/AVERAGE(G21:G34))) -> 0 | I34: =C34+2*_xlfn.STDEV.S(B15:B34) -> 0 | J34: =C34-2*_xlfn.STDEV.S(B15:B34) -> 0
A35: ='1_Precios'!A33 -> 0 | B35: =INDEX('1_Precios'!$B$33:$F$33,MATCH($B$1,'1_Precios'!$B$1:$F$1,0)) -> 0 | C35: =AVERAGE(B16:B35) -> 0 | F35: =MAX(B35-B34,0) -> 0 | G35: =MAX(B34-B35,0) -> 0 | H35: =IF(SUM(G22:G35)=0,100,100-100/(1+AVERAGE(F22:F35)/AVERAGE(G22:G35))) -> 0 | I35: =C35+2*_xlfn.STDEV.S(B16:B35) -> 0 | J35: =C35-2*_xlfn.STDEV.S(B16:B35) -> 0
A36: ='1_Precios'!A34 -> 0 | B36: =INDEX('1_Precios'!$B$34:$F$34,MATCH($B$1,'1_Precios'!$B$1:$F$1,0)) -> 0 | C36: =AVERAGE(B17:B36) -> 0 | F36: =MAX(B36-B35,0) -> 0 | G36: =MAX(B35-B36,0) -> 0 | H36: =IF(SUM(G23:G36)=0,100,100-100/(1+AVERAGE(F23:F36)/AVERAGE(G23:G36))) -> 0 | I36: =C36+2*_xlfn.STDEV.S(B17:B36) -> 0 | J36: =C36-2*_xlfn.STDEV.S(B17:B36) -> 0
A37: ='1_Precios'!A35 -> 0 | B37: =INDEX('1_Precios'!$B$35:$F$35,MATCH($B$1,'1_Precios'!$B$1:$F$1,0)) -> 0 | C37: =AVERAGE(B18:B37) -> 0 | F37: =MAX(B37-B36,0) -> 0 | G37: =MAX(B36-B37,0) -> 0 | H37: =IF(SUM(G24:G37)=0,100,100-100/(1+AVERAGE(F24:F37)/AVERAGE(G24:G37))) -> 0 | I37: =C37+2*_xlfn.STDEV.S(B18:B37) -> 0 | J37: =C37-2*_xlfn.STDEV.S(B18:B37) -> 0
A38: ='1_Precios'!A36 -> 0 | B38: =INDEX('1_Precios'!$B$36:$F$36,MATCH($B$1,'1_Precios'!$B$1:$F$1,0)) -> 0 | C38: =AVERAGE(B19:B38) -> 0 | F38: =MAX(B38-B37,0) -> 0 | G38: =MAX(B37-B38,0) -> 0 | H38: =IF(SUM(G25:G38)=0,100,100-100/(1+AVERAGE(F25:F38)/AVERAGE(G25:G38))) -> 0 | I38: =C38+2*_xlfn.STDEV.S(B19:B38) -> 0 | J38: =C38-2*_xlfn.STDEV.S(B19:B38) -> 0
A39: ='1_Precios'!A37 -> 0 | B39: =INDEX('1_Precios'!$B$37:$F$37,MATCH($B$1,'1_Precios'!$B$1:$F$1,0)) -> 0 | C39: =AVERAGE(B20:B39) -> 0 | F39: =MAX(B39-B38,0) -> 0 | G39: =MAX(B38-B39,0) -> 0 | H39: =IF(SUM(G26:G39)=0,100,100-100/(1+AVERAGE(F26:F39)/AVERAGE(G26:G39))) -> 0 | I39: =C39+2*_xlfn.STDEV.S(B20:B39) -> 0 | J39: =C39-2*_xlfn.STDEV.S(B20:B39) -> 0
A40: ='1_Precios'!A38 -> 0 | B40: =INDEX('1_Precios'!$B$38:$F$38,MATCH($B$1,'1_Precios'!$B$1:$F$1,0)) -> 0 | C40: =AVERAGE(B21:B40) -> 0 | F40: =MAX(B40-B39,0) -> 0 | G40: =MAX(B39-B40,0) -> 0 | H40: =IF(SUM(G27:G40)=0,100,100-100/(1+AVERAGE(F27:F40)/AVERAGE(G27:G40))) -> 0 | I40: =C40+2*_xlfn.STDEV.S(B21:B40) -> 0 | J40: =C40-2*_xlfn.STDEV.S(B21:B40) -> 0
A41: ='1_Precios'!A39 -> 0 | B41: =INDEX('1_Precios'!$B$39:$F$39,MATCH($B$1,'1_Precios'!$B$1:$F$1,0)) -> 0 | C41: =AVERAGE(B22:B41) -> 0 | F41: =MAX(B41-B40,0) -> 0 | G41: =MAX(B40-B41,0) -> 0 | H41: =IF(SUM(G28:G41)=0,100,100-100/(1+AVERAGE(F28:F41)/AVERAGE(G28:G41))) -> 0 | I41: =C41+2*_xlfn.STDEV.S(B22:B41) -> 0 | J41: =C41-2*_xlfn.STDEV.S(B22:B41) -> 0
...

Sheet 8_Drawdown
A1: Fecha | B1: DD BANCO | C1: DD RETAIL | D1: DD MINERA | E1: DD ENERGIA | F1: DD CONSUMO | G1: DD IPSA | I1: MAXIMO DRAWDOWN
A2: ='1_Precios'!A2 -> 0 | B2: ='1_Precios'!B2/MAX('1_Precios'!B$2:B2)-1 -> 0 | C2: ='1_Precios'!C2/MAX('1_Precios'!C$2:C2)-1 -> 0 | D2: ='1_Precios'!D2/MAX('1_Precios'!D$2:D2)-1 -> 0 | E2: ='1_Precios'!E2/MAX('1_Precios'!E$2:E2)-1 -> 0 | F2: ='1_Precios'!F2/MAX('1_Precios'!F$2:F2)-1 -> 0 | G2: ='1_Precios'!G2/MAX('1_Precios'!G$2:G2)-1 -> 0 | I2: BANCO | J2: =MIN(B2:B253) -> 0
A3: ='1_Precios'!A3 -> 0 | B3: ='1_Precios'!B3/MAX('1_Precios'!B$2:B3)-1 -> 0 | C3: ='1_Precios'!C3/MAX('1_Precios'!C$2:C3)-1 -> 0 | D3: ='1_Precios'!D3/MAX('1_Precios'!D$2:D3)-1 -> 0 | E3: ='1_Precios'!E3/MAX('1_Precios'!E$2:E3)-1 -> 0 | F3: ='1_Precios'!F3/MAX('1_Precios'!F$2:F3)-1 -> 0 | G3: ='1_Precios'!G3/MAX('1_Precios'!G$2:G3)-1 -> 0 | I3: RETAIL | J3: =MIN(C2:C253) -> 0
A4: ='1_Precios'!A4 -> 0 | B4: ='1_Precios'!B4/MAX('1_Precios'!B$2:B4)-1 -> 0 | C4: ='1_Precios'!C4/MAX('1_Precios'!C$2:C4)-1 -> 0 | D4: ='1_Precios'!D4/MAX('1_Precios'!D$2:D4)-1 -> 0 | E4: ='1_Precios'!E4/MAX('1_Precios'!E$2:E4)-1 -> 0 | F4: ='1_Precios'!F4/MAX('1_Precios'!F$2:F4)-1 -> 0 | G4: ='1_Precios'!G4/MAX('1_Precios'!G$2:G4)-1 -> 0 | I4: MINERA | J4: =MIN(D2:D253) -> 0
A5: ='1_Precios'!A5 -> 0 | B5: ='1_Precios'!B5/MAX('1_Precios'!B$2:B5)-1 -> 0 | C5: ='1_Precios'!C5/MAX('1_Precios'!C$2:C5)-1 -> 0 | D5: ='1_Precios'!D5/MAX('1_Precios'!D$2:D5)-1 -> 0 | E5: ='1_Precios'!E5/MAX('1_Precios'!E$2:E5)-1 -> 0 | F5: ='1_Precios'!F5/MAX('1_Precios'!F$2:F5)-1 -> 0 | G5: ='1_Precios'!G5/MAX('1_Precios'!G$2:G5)-1 -> 0 | I5: ENERGIA | J5: =MIN(E2:E253) -> 0
A6: ='1_Precios'!A6 -> 0 | B6: ='1_Precios'!B6/MAX('1_Precios'!B$2:B6)-1 -> 0 | C6: ='1_Precios'!C6/MAX('1_Precios'!C$2:C6)-1 -> 0 | D6: ='1_Precios'!D6/MAX('1_Precios'!D$2:D6)-1 -> 0 | E6: ='1_Precios'!E6/MAX('1_Precios'!E$2:E6)-1 -> 0 | F6: ='1_Precios'!F6/MAX('1_Precios'!F$2:F6)-1 -> 0 | G6: ='1_Precios'!G6/MAX('1_Precios'!G$2:G6)-1 -> 0 | I6: CONSUMO | J6: =MIN(F2:F253) -> 0
A7: ='1_Precios'!A7 -> 0 | B7: ='1_Precios'!B7/MAX('1_Precios'!B$2:B7)-1 -> 0 | C7: ='1_Precios'!C7/MAX('1_Precios'!C$2:C7)-1 -> 0 | D7: ='1_Precios'!D7/MAX('1_Precios'!D$2:D7)-1 -> 0 | E7: ='1_Precios'!E7/MAX('1_Precios'!E$2:E7)-1 -> 0 | F7: ='1_Precios'!F7/MAX('1_Precios'!F$2:F7)-1 -> 0 | G7: ='1_Precios'!G7/MAX('1_Precios'!G$2:G7)-1 -> 0 | I7: IPSA | J7: =MIN(G2:G253) -> 0
A8: ='1_Precios'!A8 -> 0 | B8: ='1_Precios'!B8/MAX('1_Precios'!B$2:B8)-1 -> 0 | C8: ='1_Precios'!C8/MAX('1_Precios'!C$2:C8)-1 -> 0 | D8: ='1_Precios'!D8/MAX('1_Precios'!D$2:D8)-1 -> 0 | E8: ='1_Precios'!E8/MAX('1_Precios'!E$2:E8)-1 -> 0 | F8: ='1_Precios'!F8/MAX('1_Precios'!F$2:F8)-1 -> 0 | G8: ='1_Precios'!G8/MAX('1_Precios'!G$2:G8)-1 -> 0
A9: ='1_Precios'!A9 -> 0 | B9: ='1_Precios'!B9/MAX('1_Precios'!B$2:B9)-1 -> 0 | C9: ='1_Precios'!C9/MAX('1_Precios'!C$2:C9)-1 -> 0 | D9: ='1_Precios'!D9/MAX('1_Precios'!D$2:D9)-1 -> 0 | E9: ='1_Precios'!E9/MAX('1_Precios'!E$2:E9)-1 -> 0 | F9: ='1_Precios'!F9/MAX('1_Precios'!F$2:F9)-1 -> 0 | G9: ='1_Precios'!G9/MAX('1_Precios'!G$2:G9)-1 -> 0 | I9: Drawdown = caida desde el maximo previo. Una caida de -50% exige +100% para recuperarse.
A10: ='1_Precios'!A10 -> 0 | B10: ='1_Precios'!B10/MAX('1_Precios'!B$2:B10)-1 -> 0 | C10: ='1_Precios'!C10/MAX('1_Precios'!C$2:C10)-1 -> 0 | D10: ='1_Precios'!D10/MAX('1_Precios'!D$2:D10)-1 -> 0 | E10: ='1_Precios'!E10/MAX('1_Precios'!E$2:E10)-1 -> 0 | F10: ='1_Precios'!F10/MAX('1_Precios'!F$2:F10)-1 -> 0 | G10: ='1_Precios'!G10/MAX('1_Precios'!G$2:G10)-1 -> 0
A11: ='1_Precios'!A11 -> 0 | B11: ='1_Precios'!B11/MAX('1_Precios'!B$2:B11)-1 -> 0 | C11: ='1_Precios'!C11/MAX('1_Precios'!C$2:C11)-1 -> 0 | D11: ='1_Precios'!D11/MAX('1_Precios'!D$2:D11)-1 -> 0 | E11: ='1_Precios'!E11/MAX('1_Precios'!E$2:E11)-1 -> 0 | F11: ='1_Precios'!F11/MAX('1_Precios'!F$2:F11)-1 -> 0 | G11: ='1_Precios'!G11/MAX('1_Precios'!G$2:G11)-1 -> 0
A12: ='1_Precios'!A12 -> 0 | B12: ='1_Precios'!B12/MAX('1_Precios'!B$2:B12)-1 -> 0 | C12: ='1_Precios'!C12/MAX('1_Precios'!C$2:C12)-1 -> 0 | D12: ='1_Precios'!D12/MAX('1_Precios'!D$2:D12)-1 -> 0 | E12: ='1_Precios'!E12/MAX('1_Precios'!E$2:E12)-1 -> 0 | F12: ='1_Precios'!F12/MAX('1_Precios'!F$2:F12)-1 -> 0 | G12: ='1_Precios'!G12/MAX('1_Precios'!G$2:G12)-1 -> 0
A13: ='1_Precios'!A13 -> 0 | B13: ='1_Precios'!B13/MAX('1_Precios'!B$2:B13)-1 -> 0 | C13: ='1_Precios'!C13/MAX('1_Precios'!C$2:C13)-1 -> 0 | D13: ='1_Precios'!D13/MAX('1_Precios'!D$2:D13)-1 -> 0 | E13: ='1_Precios'!E13/MAX('1_Precios'!E$2:E13)-1 -> 0 | F13: ='1_Precios'!F13/MAX('1_Precios'!F$2:F13)-1 -> 0 | G13: ='1_Precios'!G13/MAX('1_Precios'!G$2:G13)-1 -> 0
A14: ='1_Precios'!A14 -> 0 | B14: ='1_Precios'!B14/MAX('1_Precios'!B$2:B14)-1 -> 0 | C14: ='1_Precios'!C14/MAX('1_Precios'!C$2:C14)-1 -> 0 | D14: ='1_Precios'!D14/MAX('1_Precios'!D$2:D14)-1 -> 0 | E14: ='1_Precios'!E14/MAX('1_Precios'!E$2:E14)-1 -> 0 | F14: ='1_Precios'!F14/MAX('1_Precios'!F$2:F14)-1 -> 0 | G14: ='1_Precios'!G14/MAX('1_Precios'!G$2:G14)-1 -> 0
A15: ='1_Precios'!A15 -> 0 | B15: ='1_Precios'!B15/MAX('1_Precios'!B$2:B15)-1 -> 0 | C15: ='1_Precios'!C15/MAX('1_Precios'!C$2:C15)-1 -> 0 | D15: ='1_Precios'!D15/MAX('1_Precios'!D$2:D15)-1 -> 0 | E15: ='1_Precios'!E15/MAX('1_Precios'!E$2:E15)-1 -> 0 | F15: ='1_Precios'!F15/MAX('1_Precios'!F$2:F15)-1 -> 0 | G15: ='1_Precios'!G15/MAX('1_Precios'!G$2:G15)-1 -> 0
A16: ='1_Precios'!A16 -> 0 | B16: ='1_Precios'!B16/MAX('1_Precios'!B$2:B16)-1 -> 0 | C16: ='1_Precios'!C16/MAX('1_Precios'!C$2:C16)-1 -> 0 | D16: ='1_Precios'!D16/MAX('1_Precios'!D$2:D16)-1 -> 0 | E16: ='1_Precios'!E16/MAX('1_Precios'!E$2:E16)-1 -> 0 | F16: ='1_Precios'!F16/MAX('1_Precios'!F$2:F16)-1 -> 0 | G16: ='1_Precios'!G16/MAX('1_Precios'!G$2:G16)-1 -> 0
A17: ='1_Precios'!A17 -> 0 | B17: ='1_Precios'!B17/MAX('1_Precios'!B$2:B17)-1 -> 0 | C17: ='1_Precios'!C17/MAX('1_Precios'!C$2:C17)-1 -> 0 | D17: ='1_Precios'!D17/MAX('1_Precios'!D$2:D17)-1 -> 0 | E17: ='1_Precios'!E17/MAX('1_Precios'!E$2:E17)-1 -> 0 | F17: ='1_Precios'!F17/MAX('1_Precios'!F$2:F17)-1 -> 0 | G17: ='1_Precios'!G17/MAX('1_Precios'!G$2:G17)-1 -> 0
A18: ='1_Precios'!A18 -> 0 | B18: ='1_Precios'!B18/MAX('1_Precios'!B$2:B18)-1 -> 0 | C18: ='1_Precios'!C18/MAX('1_Precios'!C$2:C18)-1 -> 0 | D18: ='1_Precios'!D18/MAX('1_Precios'!D$2:D18)-1 -> 0 | E18: ='1_Precios'!E18/MAX('1_Precios'!E$2:E18)-1 -> 0 | F18: ='1_Precios'!F18/MAX('1_Precios'!F$2:F18)-1 -> 0 | G18: ='1_Precios'!G18/MAX('1_Precios'!G$2:G18)-1 -> 0
A19: ='1_Precios'!A19 -> 0 | B19: ='1_Precios'!B19/MAX('1_Precios'!B$2:B19)-1 -> 0 | C19: ='1_Precios'!C19/MAX('1_Precios'!C$2:C19)-1 -> 0 | D19: ='1_Precios'!D19/MAX('1_Precios'!D$2:D19)-1 -> 0 | E19: ='1_Precios'!E19/MAX('1_Precios'!E$2:E19)-1 -> 0 | F19: ='1_Precios'!F19/MAX('1_Precios'!F$2:F19)-1 -> 0 | G19: ='1_Precios'!G19/MAX('1_Precios'!G$2:G19)-1 -> 0
A20: ='1_Precios'!A20 -> 0 | B20: ='1_Precios'!B20/MAX('1_Precios'!B$2:B20)-1 -> 0 | C20: ='1_Precios'!C20/MAX('1_Precios'!C$2:C20)-1 -> 0 | D20: ='1_Precios'!D20/MAX('1_Precios'!D$2:D20)-1 -> 0 | E20: ='1_Precios'!E20/MAX('1_Precios'!E$2:E20)-1 -> 0 | F20: ='1_Precios'!F20/MAX('1_Precios'!F$2:F20)-1 -> 0 | G20: ='1_Precios'!G20/MAX('1_Precios'!G$2:G20)-1 -> 0
A21: ='1_Precios'!A21 -> 0 | B21: ='1_Precios'!B21/MAX('1_Precios'!B$2:B21)-1 -> 0 | C21: ='1_Precios'!C21/MAX('1_Precios'!C$2:C21)-1 -> 0 | D21: ='1_Precios'!D21/MAX('1_Precios'!D$2:D21)-1 -> 0 | E21: ='1_Precios'!E21/MAX('1_Precios'!E$2:E21)-1 -> 0 | F21: ='1_Precios'!F21/MAX('1_Precios'!F$2:F21)-1 -> 0 | G21: ='1_Precios'!G21/MAX('1_Precios'!G$2:G21)-1 -> 0
... A253: ='1_Precios'!A253 -> 0 | B253: ='1_Precios'!B253/MAX('1_Precios'!B$2:B253)-1 -> 0 | C253: ='1_Precios'!C253/MAX('1_Precios'!C$2:C253)-1 -> 0 | D253: ='1_Precios'!D253/MAX('1_Precios'!D$2:D253)-1 -> 0 | E253: ='1_Precios'!E253/MAX('1_Precios'!E$2:E253)-1 -> 0 | F253: ='1_Precios'!F253/MAX('1_Precios'!F$2:F253)-1 -> 0 | G253: ='1_Precios'!G253/MAX('1_Precios'!G$2:G253)-1 -> 0

Sheet 9_Simulador_CCI
A1: CUADERNO DE OPERACIONES - CCI
A2: Registra cada operacion tal como la hiciste en el simulador. Las filas de ejemplo son ficticias: borralas antes de empezar.
A4: Capital inicial | C4: 20000000 | F4: IPSA al inicio | H4: 10000 | N4: RESUMEN DE LA CARTERA
A5: Comision por operacion | C5: 0.005 | D5: Confirmar en bases vigentes | F5: IPSA hoy | H5: 10250 | N5: Caja disponible | O5: =$C$4+SUM(H11:H110) -> 0 | P5: Alerta
A6: Limite de peso por accion | C6: 0.35 | D6: Tu regla de riesgo | N6: Valor de mercado acciones | O6: =SUM(T13:T27) -> 0 | P6: =IF(O5<0,"CAJA NEGATIVA",IF(MAX(V13:V27)>$C$6,"CONCENTRACION > limite","OK")) -> 0
N7: VALOR TOTAL CARTERA | O7: =O5+O6 -> 0
N8: Rentabilidad acumulada | O8: =O7/$C$4-1 -> 0
N9: Rentabilidad IPSA mismo periodo | O9: =$H$5/$H$4-1 -> 0
A10: Fecha | B10: Ticker | C10: Tipo | D10: Cantidad | E10: Precio | F10: Monto bruto | G10: Comision | H10: Flujo de caja | I10: Cant. +/- | J10: Tesis / motivo | K10: Stop | L10: Objetivo | N10: Exceso sobre IPSA | O10: =O8-O9 -> 0
